<?xml version="1.0" ?>
<!-- Generated using onshape-to-robot -->
<!-- Onshape https://cad.onshape.com/documents/3db3f528a96d85e8010d4142/w/dee4678f56d2c9eb687ef9c8/e/7b205b6cc182a95f765c40a2 -->
<mujoco model="SundayA1_Mujoco">
  <compiler angle="radian" meshdir="assets" autolimits="true"/>
  <default>
    <default class="SundayA1_Mujoco">
      <joint frictionloss="0.1" armature="0.005"/>
      <position kp="50" dampratio="1"/>
      <default class="visual">
        <geom type="mesh" contype="0" conaffinity="0" group="2"/>
      </default>
      <default class="collision">
        <geom group="3"/>
      </default>
    </default>
  </default>
  <worldbody>
    <!-- Link body -->
    <body name="body" pos="0 0 0.2615" quat="1 0 0 0" childclass="SundayA1_Mujoco">
      <freejoint name="base"/>
      <inertial pos="-6.33681e-06 0.0282241 0.0910197" mass="1.01051" fullinertia="0.00617079 0.00804533 0.00309803 6.75776e-08 1.86326e-05 -0.00023831"/>
      <!-- Part sts3215 -->
      <geom type="mesh" class="visual" pos="0.159553 0.083903 0.0743641" quat="0.298836 0.640856 -0.640856 -0.298836" mesh="sts3215" material="sts3215_material"/>
      <!-- <geom type="mesh" class="collision" pos="0.159553 0.083903 0.0743641" quat="0.298836 0.640856 -0.640856 -0.298836" mesh="sts3215" material="sts3215_material"/> -->
      <!-- Part main_torso1204 -->
      <geom type="mesh" class="visual" pos="4.68418e-10 0.019393 0.0863814" quat="1 0 0 0" mesh="main_torso1204" material="main_torso1204_material"/>
      <!-- <geom type="mesh" class="collision" pos="4.68418e-10 0.019393 0.0863814" quat="1 0 0 0" mesh="main_torso1204" material="main_torso1204_material"/> -->
      <!-- Part leg_foundation1029 -->
      <geom type="mesh" class="visual" pos="0.0340959 0.019393 -0.0047984" quat="0.241845 0.664463 0.664463 0.241845" mesh="leg_foundation1029" material="leg_foundation1029_material"/>
      <!-- <geom type="mesh" class="collision" pos="0.0340959 0.019393 -0.0047984" quat="0.241845 0.664463 0.664463 0.241845" mesh="leg_foundation1029" material="leg_foundation1029_material"/> -->
      <!-- Part sts3215_2 -->
      <geom type="mesh" class="visual" pos="-0.159392 -0.045117 0.0745556" quat="0.298836 0.640856 0.640856 0.298836" mesh="sts3215" material="sts3215_material"/>
      <!-- <geom type="mesh" class="collision" pos="-0.159392 -0.045117 0.0745556" quat="0.298836 0.640856 0.640856 0.298836" mesh="sts3215" material="sts3215_material"/> -->
      <!-- Part sts3215_3 -->
      <geom type="mesh" class="visual" pos="0.06451 0.028593 0.334808" quat="2.47644e-21 5.72049e-17 -1 -1.24325e-19" mesh="sts3215" material="sts3215_material"/>
      <!-- <geom type="mesh" class="collision" pos="0.06451 0.028593 0.334808" quat="2.47644e-21 5.72049e-17 -1 -1.24325e-19" mesh="sts3215" material="sts3215_material"/> -->
      <!-- Part sts3215_4 -->
      <geom type="mesh" class="visual" pos="0.218533 -0.045117 0.159381" quat="0.5 -0.5 -0.5 0.5" mesh="sts3215" material="sts3215_material"/>
      <!-- <geom type="mesh" class="collision" pos="0.218533 -0.045117 0.159381" quat="0.5 -0.5 -0.5 0.5" mesh="sts3215" material="sts3215_material"/> -->
      <!-- Part internal_weight_395g__configuration_default -->
      <geom type="mesh" class="visual" pos="-0.0357255 0.00939298 0.0588814" quat="0.707107 -0.707107 -0 -2.83195e-29" mesh="internal_weight_395g__configuration_default" material="internal_weight_395g__configuration_default_material"/>
      <!-- <geom type="mesh" class="collision" pos="-0.0357255 0.00939298 0.0588814" quat="0.707107 -0.707107 -0 -2.83195e-29" mesh="internal_weight_395g__configuration_default" material="internal_weight_395g__configuration_default_material"/> -->
      <!-- Part sts3215_5 -->
      <geom type="mesh" class="visual" pos="-0.218533 0.083903 0.163135" quat="0.5 -0.5 0.5 -0.5" mesh="sts3215" material="sts3215_material"/>
      <!-- <geom type="mesh" class="collision" pos="-0.218533 0.083903 0.163135" quat="0.5 -0.5 0.5 -0.5" mesh="sts3215" material="sts3215_material"/> -->
      <!-- Part leg_foundation1029_2 -->
      <geom type="mesh" class="visual" pos="-0.0340959 0.019393 -0.0047984" quat="0.241845 0.664463 -0.664463 -0.241845" mesh="leg_foundation1029" material="leg_foundation1029_material"/>
      <!-- <geom type="mesh" class="collision" pos="-0.0340959 0.019393 -0.0047984" quat="0.241845 0.664463 -0.664463 -0.241845" mesh="leg_foundation1029" material="leg_foundation1029_material"/> -->
      <!-- Link head1209 -->
      <body name="head1209" pos="4.68418e-10 0.019843 0.206868" quat="1.00787e-15 0.715014 0.699111 4.53256e-16">
        <!-- Joint from body to head1209 -->
        <joint axis="0 0 1" name="head_yaw" type="hinge" range="-1 1" frictionloss="0.052" armature="0.028" damping="0"/>
        <inertial pos="0 0 0" mass="1e-09" fullinertia="1e-09 1e-09 1e-09 0 0 0"/>
        <!-- Part head1209 -->
        <geom type="mesh" class="visual" pos="0.0225 1.59378e-17 -0.09" quat="6.28037e-17 0.707107 -0.707107 6.28037e-17" mesh="head1209" material="head1209_material"/>
        <!-- <geom type="mesh" class="collision" pos="0.0225 1.59378e-17 -0.09" quat="6.28037e-17 0.707107 -0.707107 6.28037e-17" mesh="head1209" material="head1209_material"/> -->
        <!-- Part realsense_d435i -->
        <geom type="mesh" class="visual" pos="0.00146458 1.49132e-16 -0.0981134" quat="0.612372 -0.353553 0.353553 -0.612372" mesh="realsense_d435i" material="realsense_d435i_material"/>
        <!-- <geom type="mesh" class="collision" pos="0.00146458 1.49132e-16 -0.0981134" quat="0.612372 -0.353553 0.353553 -0.612372" mesh="realsense_d435i" material="realsense_d435i_material"/> -->
      </body>
      <!-- Link shoulder -->
      <body name="shoulder" pos="0.0529429 0.019393 0.169381" quat="0.5 -0.5 -0.5 0.5">
        <!-- Joint from body to shoulder -->
        <joint axis="0 0 1" name="right_shoulder_pitch" type="hinge" range="-0.785 0.785" frictionloss="0.052" armature="0.028" damping="0"/>
        <inertial pos="1.67842e-06 -0.00189479 -0.0610929" mass="0.0774183" fullinertia="4.4129e-05 3.67208e-05 1.80135e-05 2.034e-09 8.40956e-09 2.5442e-06"/>
        <!-- Part shoulder1019 -->
        <geom type="mesh" class="visual" pos="2.77556e-17 -1.11022e-16 -0.018825" quat="1.16573e-15 1.36326e-15 -0.707107 -0.707107" mesh="shoulder1019" material="shoulder1019_material"/>
        <!-- <geom type="mesh" class="collision" pos="2.77556e-17 -1.11022e-16 -0.018825" quat="1.16573e-15 1.36326e-15 -0.707107 -0.707107" mesh="shoulder1019" material="shoulder1019_material"/> -->
        <!-- Part sts3215_6 -->
        <geom type="mesh" class="visual" pos="0.06451 -0.14699 -0.067756" quat="1.66533e-15 1.39492e-15 -0.707107 -0.707107" mesh="sts3215" material="sts3215_material"/>
        <!-- <geom type="mesh" class="collision" pos="0.06451 -0.14699 -0.067756" quat="1.66533e-15 1.39492e-15 -0.707107 -0.707107" mesh="sts3215" material="sts3215_material"/> -->
        <!-- Link deltoid -->
        <body name="deltoid" pos="1.04083e-16 -0.01905 -0.077756" quat="1.66533e-15 1.39492e-15 -0.707107 -0.707107">
          <!-- Joint from shoulder to deltoid -->
          <joint axis="0 0 1" name="right_shoulder_yaw" type="hinge" frictionloss="0.052" armature="0.028" damping="0"/>
          <inertial pos="-9.35746e-17 -0.0107349 0.0263596" mass="0.0153484" fullinertia="8.20048e-06 1.08234e-05 4.71676e-06 2.61736e-20 -1.07178e-20 -7.91036e-07"/>
          <!-- Part deltoid -->
          <geom type="mesh" class="visual" pos="0 0 0.038" quat="0.5 -0.5 -0.5 0.5" mesh="deltoid" material="deltoid_material"/>
          <!-- <geom type="mesh" class="collision" pos="0 0 0.038" quat="0.5 -0.5 -0.5 0.5" mesh="deltoid" material="deltoid_material"/> -->
          <!-- Link elbow -->
          <body name="elbow" pos="-0.019 1.66533e-16 0.059" quat="0.5 -0.5 -0.5 0.5">
            <!-- Joint from deltoid to elbow -->
            <joint axis="0 0 1" name="right_elbow" type="hinge" range="-1.3 1.7" frictionloss="0.052" armature="0.028" damping="0"/>
            <inertial pos="-1.59266e-06 -0.0175591 -0.0180498" mass="0.0815874" fullinertia="4.68725e-05 2.32792e-05 4.49069e-05 8.52598e-09 2.15025e-09 -5.47454e-07"/>
            <!-- Part elbow1216 -->
            <geom type="mesh" class="visual" pos="1.66533e-16 -0.026159 -0.01905" quat="0.707107 -0.707107 -1.33227e-15 -1.05551e-14" mesh="elbow1216" material="elbow1216_material"/>
            <!-- <geom type="mesh" class="collision" pos="1.66533e-16 -0.026159 -0.01905" quat="0.707107 -0.707107 -1.33227e-15 -1.05551e-14" mesh="elbow1216" material="elbow1216_material"/> -->
            <!-- Part sts3215_7 -->
            <geom type="mesh" class="visual" pos="-0.06451 -0.01 0.12794" quat="0 1 0 0" mesh="sts3215" material="sts3215_material"/>
            <!-- <geom type="mesh" class="collision" pos="-0.06451 -0.01 0.12794" quat="0 1 0 0" mesh="sts3215" material="sts3215_material"/> -->
            <!-- Link right_hand -->
            <body name="right_hand" pos="0.018825 -0.08 -0.01905" quat="2.23777e-14 0.707107 -3.33067e-16 0.707107">
              <!-- Joint from elbow to right_hand -->
              <joint axis="0 0 1" name="right_wrist" type="hinge" range="-1 1" frictionloss="0.052" armature="0.028" damping="0"/>
              <inertial pos="-0.000401271 0.0351207 -0.0196971" mass="0.148715" fullinertia="0.000122296 4.42743e-05 0.000120903 4.0377e-06 2.24098e-07 -5.86037e-07"/>
              <!-- Part paw1018 -->
              <geom type="mesh" class="visual" pos="0.00025 0.0492539 -0.0346" quat="0.5 -0.5 0.5 0.5" mesh="paw1018" material="paw1018_material"/>
              <!-- <geom type="mesh" class="collision" pos="0.00025 0.0492539 -0.0346" quat="0.5 -0.5 0.5 0.5" mesh="paw1018" material="paw1018_material"/> -->
              <!-- Part sts3215_8 -->
              <geom type="mesh" class="visual" pos="0.002804 -0.0122561 -0.16559" quat="0.707107 -7.88243e-17 -3.60822e-16 0.707107" mesh="sts3215" material="sts3215_material"/>
              <!-- <geom type="mesh" class="collision" pos="0.002804 -0.0122561 -0.16559" quat="0.707107 -7.88243e-17 -3.60822e-16 0.707107" mesh="sts3215" material="sts3215_material"/> -->
              <!-- Part sts3215_9 -->
              <geom type="mesh" class="visual" pos="-0.06451 0.01 -0.16559" quat="1 -0 -2.22045e-16 -1.66533e-16" mesh="sts3215" material="sts3215_material"/>
              <!-- <geom type="mesh" class="collision" pos="-0.06451 0.01 -0.16559" quat="1 -0 -2.22045e-16 -1.66533e-16" mesh="sts3215" material="sts3215_material"/> -->
              <!-- Link thumb1019 -->
              <body name="thumb1019" pos="0.012804 0.0522539 -0.03765" quat="0.707107 -7.88243e-17 -3.60822e-16 0.707107">
                <!-- Joint from right_hand to thumb1019 -->
                <joint axis="0 0 1" name="right_hand" type="hinge" range="-2.5 0" frictionloss="0.052" armature="0.028" damping="0"/>
                <inertial pos="0.0253801 0.00703901 0.018825" mass="0.0104688" fullinertia="2.3125e-06 4.40128e-06 3.0148e-06 -5.65324e-07 -3.76786e-13 -1.03746e-13"/>
                <!-- Part thumb1019 -->
                <geom type="mesh" class="visual" pos="-1.73472e-18 -1.38778e-17 0.018825" quat="0.5 0.5 0.5 0.5" mesh="thumb1019" material="thumb1019_material"/>
                <!-- <geom type="mesh" class="collision" pos="-1.73472e-18 -1.38778e-17 0.018825" quat="0.5 0.5 0.5 0.5" mesh="thumb1019" material="thumb1019_material"/> -->
              </body>
            </body>
          </body>
        </body>
      </body>
      <!-- Link hip -->
      <body name="hip" pos="0.0679727 0.019393 -0.0155346" quat="0.298836 0.640856 -0.640856 -0.298836">
        <!-- Joint from body to hip -->
        <joint axis="0 0 1" name="right_hip_roll" type="hinge" range="-1 1" frictionloss="0.052" armature="0.028" damping="0"/>
        <inertial pos="0.00106942 -0.0359263 0.0188233" mass="0.0762186" fullinertia="2.6454e-05 1.91185e-05 3.06014e-05 2.66827e-07 2.14125e-09 -8.07308e-09"/>
        <!-- Part sts3215_10 -->
        <geom type="mesh" class="visual" pos="0.14699 -0.04 -0.045685" quat="0.707107 1.95106e-15 -0.707107 -2.16493e-15" mesh="sts3215" material="sts3215_material"/>
        <!-- <geom type="mesh" class="collision" pos="0.14699 -0.04 -0.045685" quat="0.707107 1.95106e-15 -0.707107 -2.16493e-15" mesh="sts3215" material="sts3215_material"/> -->
        <!-- Part hips1016 -->
        <geom type="mesh" class="visual" pos="0.016 0 0.018825" quat="0.707107 -0.707107 0 -4.06039e-30" mesh="hips1016" material="hips1016_material"/>
        <!-- <geom type="mesh" class="collision" pos="0.016 0 0.018825" quat="0.707107 -0.707107 0 -4.06039e-30" mesh="hips1016" material="hips1016_material"/> -->
        <!-- Link low_hip -->
        <body name="low_hip" pos="0.01905 -0.05 0.018825" quat="0.298836 -0.640856 -0.298836 0.640856">
          <!-- Joint from hip to low_hip -->
          <joint axis="0 0 1" name="right_hip_pitch" type="hinge" range="-1.6 1.6" frictionloss="0.052" armature="0.028" damping="0"/>
          <inertial pos="-0.0417421 -1.66285e-06 0.00770428" mass="0.0781435" fullinertia="2.36153e-05 3.70364e-05 2.44894e-05 1.72693e-09 -2.62202e-06 7.68937e-09"/>
          <!-- Part sts3215_11 -->
          <geom type="mesh" class="visual" pos="0.10099 -0.06451 0.008825" quat="0.5 -0.5 -0.5 0.5" mesh="sts3215" material="sts3215_material"/>
          <!-- <geom type="mesh" class="collision" pos="0.10099 -0.06451 0.008825" quat="0.5 -0.5 -0.5 0.5" mesh="sts3215" material="sts3215_material"/> -->
          <!-- Part thigh1016 -->
          <geom type="mesh" class="visual" pos="-0.03 0 -0.031175" quat="6.91522e-15 -1 0 1.30649e-30" mesh="thigh1016" material="thigh1016_material"/>
          <!-- <geom type="mesh" class="collision" pos="-0.03 0 -0.031175" quat="6.91522e-15 -1 0 1.30649e-30" mesh="thigh1016" material="thigh1016_material"/> -->
          <!-- Link knee_down -->
          <body name="knee_down" pos="-0.02695 -5.82867e-16 0.018825" quat="0.707107 -3.52736e-14 0.707107 -3.55488e-14">
            <!-- Joint from low_hip to knee_down -->
            <joint axis="0 0 1" name="right_hip_yaw" type="hinge" range="-0.785 0.785" frictionloss="0.052" armature="0.028" damping="0"/>
            <inertial pos="-0.0107349 2.38445e-18 -0.0263596" mass="0.0153484" fullinertia="1.08234e-05 8.20048e-06 4.71676e-06 -4.82763e-35 7.91036e-07 -6.4902e-37"/>
            <!-- Part knee_down -->
            <geom type="mesh" class="visual" pos="0 0 -0.038" quat="0.707107 0.707107 0 9.08309e-31" mesh="knee_down" material="knee_down_material"/>
            <!-- <geom type="mesh" class="collision" pos="0 0 -0.038" quat="0.707107 0.707107 0 9.08309e-31" mesh="knee_down" material="knee_down_material"/> -->
            <!-- Link knee -->
            <body name="knee" pos="-3.46945e-18 0.019 -0.059" quat="2.37258e-14 2.40725e-14 -0.707107 0.707107">
              <!-- Joint from knee_down to knee -->
              <joint axis="0 0 1" name="right_knee" type="hinge" range="-1.23 1.6" frictionloss="0.052" armature="0.028" damping="0"/>
              <inertial pos="-1.7237e-06 0.0139003 0.0179711" mass="0.0753846" fullinertia="3.1566e-05 1.85785e-05 2.44068e-05 -8.05055e-09 -2.14001e-09 -2.57668e-07"/>
              <!-- Part calf1016 -->
              <geom type="mesh" class="visual" pos="-2.77556e-17 0.05 0.00305001" quat="0.5 -0.5 0.5 0.5" mesh="calf1016" material="calf1016_material"/>
              <!-- <geom type="mesh" class="collision" pos="-2.77556e-17 0.05 0.00305001" quat="0.5 -0.5 0.5 0.5" mesh="calf1016" material="calf1016_material"/> -->
              <!-- Part sts3215_12 -->
              <geom type="mesh" class="visual" pos="-0.06451 0.01 -0.12794" quat="1 0 -3.33067e-16 2.77556e-17" mesh="sts3215" material="sts3215_material"/>
              <!-- <geom type="mesh" class="collision" pos="-0.06451 0.01 -0.12794" quat="1 0 -3.33067e-16 2.77556e-17" mesh="sts3215" material="sts3215_material"/> -->
              <!-- Link sts3215 -->
              <body name="sts3215" pos="-1.04083e-17 0.05 0.000225009" quat="2.77556e-17 1 2.95598e-14 -1.8686e-17">
                <!-- Joint from knee to sts3215 -->
                <joint axis="0 0 1" name="right_ankle_pitch" type="hinge" frictionloss="0.052" armature="0.028" damping="0"/>
                <inertial pos="-0.0253257 -0.0124337 -0.0184991" mass="0.146992" fullinertia="4.78763e-05 0.00012758 0.000141025 4.2529e-07 -2.05288e-06 -1.50896e-07"/>
                <!-- Part right_ankle0120 -->
                <geom type="mesh" class="visual" pos="-3.46945e-17 -0.035 -0.01905" quat="7.27025e-17 3.63999e-17 5.93931e-17 -1" mesh="right_ankle0120" material="right_ankle0120_material"/>
                <!-- <geom type="mesh" class="collision" pos="-3.46945e-17 -0.035 -0.01905" quat="7.27025e-17 3.63999e-17 5.93931e-17 -1" mesh="right_ankle0120" material="right_ankle0120_material"/> -->
                <!-- Part sts3215_13 -->
                <geom type="mesh" class="visual" pos="0.09499 -0.014834 -0.08356" quat="0.707107 8.40252e-17 -0.707107 -1.11022e-16" mesh="sts3215" material="sts3215_material"/>
                <!-- <geom type="mesh" class="collision" pos="0.09499 -0.014834 -0.08356" quat="0.707107 8.40252e-17 -0.707107 -1.11022e-16" mesh="sts3215" material="sts3215_material"/> -->
                <!-- Part sts3215_14 -->
                <geom type="mesh" class="visual" pos="-0.06451 -0.01 0.12794" quat="0 1 0 0" mesh="sts3215" material="sts3215_material"/>
                <!-- <geom type="mesh" class="collision" pos="-0.06451 -0.01 0.12794" quat="0 1 0 0" mesh="sts3215" material="sts3215_material"/> -->
                <!-- Link right_foot0120 -->
                <body name="right_foot0120" pos="-0.03295 -0.024834 -0.01905" quat="1.31441e-15 0.707107 1.33227e-15 -0.707107">
                  <!-- Joint from sts3215 to right_foot0120 -->
                  <joint axis="0 0 1" name="right_ankle_roll" type="hinge" frictionloss="0.052" armature="0.028" damping="0"/>
                  <inertial pos="-0.015468 0.0283055 -0.0290089" mass="0.0697141" fullinertia="0.000177573 0.00021292 4.0677e-05 1.74827e-06 -3.58318e-06 2.99215e-06"/>
                  <!-- Part right_foot0120 -->
                  <geom type="mesh" class="visual" pos="-0.016 0.01 0.018825" quat="0.707107 0.707107 -0 -5.08798e-30" mesh="right_foot0120" material="right_foot0120_material"/>
                  <!-- <geom type="mesh" class="collision" pos="-0.016 0.01 0.018825" quat="0.707107 0.707107 -0 -5.08798e-30" mesh="right_foot0120" material="right_foot0120_material"/> -->
                  <geom name="foot_collider_right" type="box" class="collision" pos="-0.017 0.030 -0.033" size="0.04 0.005 0.09" material="collision_material"/>
                </body>
              </body>
            </body>
          </body>
        </body>
      </body>
      <!-- Link shoulder_2 -->
      <body name="shoulder_2" pos="-0.0529429 0.019393 0.173135" quat="0.5 0.5 -0.5 -0.5">
        <!-- Joint from body to shoulder_2 -->
        <joint axis="0 0 1" name="left_shoulder_pitch" type="hinge" range="-0.785 0.785" frictionloss="0.052" armature="0.028" damping="0"/>
        <inertial pos="1.67842e-06 0.00189479 0.0610929" mass="0.0774183" fullinertia="4.4129e-05 3.67208e-05 1.80135e-05 -2.034e-09 -8.40956e-09 2.5442e-06"/>
        <!-- Part shoulder1019_2 -->
        <geom type="mesh" class="visual" pos="-2.42861e-17 1.11022e-16 0.018825" quat="1.11022e-16 3.58924e-17 -0.707107 0.707107" mesh="shoulder1019" material="shoulder1019_material"/>
        <!-- <geom type="mesh" class="collision" pos="-2.42861e-17 1.11022e-16 0.018825" quat="1.11022e-16 3.58924e-17 -0.707107 0.707107" mesh="shoulder1019" material="shoulder1019_material"/> -->
        <!-- Part sts3215_15 -->
        <geom type="mesh" class="visual" pos="0.06451 0.14699 0.067756" quat="2.22045e-16 2.24276e-17 -0.707107 0.707107" mesh="sts3215" material="sts3215_material"/>
        <!-- <geom type="mesh" class="collision" pos="0.06451 0.14699 0.067756" quat="2.22045e-16 2.24276e-17 -0.707107 0.707107" mesh="sts3215" material="sts3215_material"/> -->
        <!-- Link deltoid_2 -->
        <body name="deltoid_2" pos="-5.20417e-17 0.01905 0.077756" quat="0.5 0.5 0.5 -0.5">
          <!-- Joint from shoulder_2 to deltoid_2 -->
          <joint axis="0 0 1" name="left_shoulder_roll" type="hinge" range="-1.7 1.7" frictionloss="0.052" armature="0.028" damping="0"/>
          <inertial pos="-0.0107349 -4.45126e-18 0.0263596" mass="0.0153484" fullinertia="1.08234e-05 8.20048e-06 4.71676e-06 -9.94718e-37 -7.91036e-07 5.39905e-38"/>
          <!-- Part deltoid_2 -->
          <geom type="mesh" class="visual" pos="0 0 0.038" quat="0.707107 -0.707107 0 -7.33265e-33" mesh="deltoid" material="deltoid_material"/>
          <!-- <geom type="mesh" class="collision" pos="0 0 0.038" quat="0.707107 -0.707107 0 -7.33265e-33" mesh="deltoid" material="deltoid_material"/> -->
          <!-- Link elbow_2 -->
          <body name="elbow_2" pos="-2.77556e-17 0.019 0.059" quat="2.22045e-16 5.90748e-16 -0.707107 0.707107">
            <!-- Joint from deltoid_2 to elbow_2 -->
            <joint axis="0 0 1" name="left_elbow" type="hinge" range="-1.7 1.3" frictionloss="0.052" armature="0.028" damping="0"/>
            <inertial pos="-1.59266e-06 -0.0175591 0.0196002" mass="0.0815874" fullinertia="4.68725e-05 2.32792e-05 4.49069e-05 8.52598e-09 2.15025e-09 -5.47454e-07"/>
            <!-- Part elbow1216_2 -->
            <geom type="mesh" class="visual" pos="-5.55112e-17 -0.026159 0.0186" quat="0.707107 -0.707107 4.44089e-16 -5.91957e-16" mesh="elbow1216" material="elbow1216_material"/>
            <!-- <geom type="mesh" class="collision" pos="-5.55112e-17 -0.026159 0.0186" quat="0.707107 -0.707107 4.44089e-16 -5.91957e-16" mesh="elbow1216" material="elbow1216_material"/> -->
            <!-- Part sts3215_16 -->
            <geom type="mesh" class="visual" pos="-0.06451 -0.01 0.16559" quat="0 1 0 0" mesh="sts3215" material="sts3215_material"/>
            <!-- <geom type="mesh" class="collision" pos="-0.06451 -0.01 0.16559" quat="0 1 0 0" mesh="sts3215" material="sts3215_material"/> -->
            <!-- Link left_hand -->
            <body name="left_hand" pos="0.018825 -0.08 0.0186" quat="0.707107 2.00268e-16 0.707107 7.21645e-16">
              <!-- Joint from elbow_2 to left_hand -->
              <joint axis="0 0 1" name="left_wrist" type="hinge" range="-1 1" frictionloss="0.052" armature="0.028" damping="0"/>
              <inertial pos="0.000423139 -0.0355726 -0.0179529" mass="0.148715" fullinertia="0.000124841 4.4259e-05 0.000123433 4.12569e-06 2.27795e-07 -5.90332e-07"/>
              <!-- Part sts3215_17 -->
              <geom type="mesh" class="visual" pos="-0.06451 -0.01 0.12794" quat="0 1 0 0" mesh="sts3215" material="sts3215_material"/>
              <!-- <geom type="mesh" class="collision" pos="-0.06451 -0.01 0.12794" quat="0 1 0 0" mesh="sts3215" material="sts3215_material"/> -->
              <!-- Part sts3215_18 -->
              <geom type="mesh" class="visual" pos="-0.00275 -0.117564 0.12794" quat="2.38485e-15 0.707107 0.707107 -1.05706e-15" mesh="sts3215" material="sts3215_material"/>
              <!-- <geom type="mesh" class="collision" pos="-0.00275 -0.117564 0.12794" quat="2.38485e-15 0.707107 0.707107 -1.05706e-15" mesh="sts3215" material="sts3215_material"/> -->
              <!-- Part paw1018_left -->
              <geom type="mesh" class="visual" pos="-0.00025 -0.0500539 -0.00305001" quat="0.5 0.5 -0.5 0.5" mesh="paw1018_left" material="paw1018_left_material"/>
              <!-- <geom type="mesh" class="collision" pos="-0.00025 -0.0500539 -0.00305001" quat="0.5 0.5 -0.5 0.5" mesh="paw1018_left" material="paw1018_left_material"/> -->
              <!-- Link thumb1019_2 -->
              <body name="thumb1019_2" pos="-0.01275 -0.0530539 -6.93889e-16" quat="2.38485e-15 0.707107 0.707107 -1.05706e-15">
                <!-- Joint from left_hand to thumb1019_2 -->
                <joint axis="0 0 1" name="left_hand" type="hinge" range="0 2.5" frictionloss="0.052" armature="0.028" damping="0"/>
                <inertial pos="-0.0253801 0.00703901 0.018825" mass="0.0104688" fullinertia="2.3125e-06 4.40128e-06 3.0148e-06 5.65324e-07 -3.76786e-13 1.03746e-13"/>
                <!-- Part thumb1019_2 -->
                <geom type="mesh" class="visual" pos="-2.1684e-18 6.93889e-18 0.018825" quat="0.5 -0.5 -0.5 0.5" mesh="thumb1019" material="thumb1019_material"/>
                <!-- <geom type="mesh" class="collision" pos="-2.1684e-18 6.93889e-18 0.018825" quat="0.5 -0.5 -0.5 0.5" mesh="thumb1019" material="thumb1019_material"/> -->
              </body>
            </body>
          </body>
        </body>
      </body>
      <!-- Link hip_2 -->
      <body name="hip_2" pos="-0.067812 0.019393 -0.0153431" quat="0.298836 0.640856 0.640856 0.298836">
        <!-- Joint from body to hip_2 -->
        <joint axis="0 0 1" name="left_hip_roll" type="hinge" range="-1 1" frictionloss="0.052" armature="0.028" damping="0"/>
        <inertial pos="0.00106942 -0.0359263 0.0188233" mass="0.0762186" fullinertia="2.6454e-05 1.91185e-05 3.06014e-05 2.66827e-07 2.14125e-09 -8.07308e-09"/>
        <!-- Part sts3215_19 -->
        <geom type="mesh" class="visual" pos="0.14699 -0.04 -0.045685" quat="0.707107 7.88498e-16 -0.707107 -1.11022e-16" mesh="sts3215" material="sts3215_material"/>
        <!-- <geom type="mesh" class="collision" pos="0.14699 -0.04 -0.045685" quat="0.707107 7.88498e-16 -0.707107 -1.11022e-16" mesh="sts3215" material="sts3215_material"/> -->
        <!-- Part hips1016_2 -->
        <geom type="mesh" class="visual" pos="0.016 0 0.018825" quat="0.707107 -0.707107 0 1.53568e-31" mesh="hips1016" material="hips1016_material"/>
        <!-- <geom type="mesh" class="collision" pos="0.016 0 0.018825" quat="0.707107 -0.707107 0 1.53568e-31" mesh="hips1016" material="hips1016_material"/> -->
        <!-- Link low_hip_2 -->
        <body name="low_hip_2" pos="-0.0186 -0.05 0.018825" quat="0.640856 0.298836 0.640856 0.298836">
          <!-- Joint from hip_2 to low_hip_2 -->
          <joint axis="0 0 1" name="left_hip_pitch" type="hinge" range="-1.6 1.6" frictionloss="0.052" armature="0.028" damping="0"/>
          <inertial pos="-0.0417421 -1.66285e-06 0.00770428" mass="0.0781435" fullinertia="2.36153e-05 3.70364e-05 2.44894e-05 1.72693e-09 -2.62202e-06 7.68937e-09"/>
          <!-- Part sts3215_20 -->
          <geom type="mesh" class="visual" pos="0.10099 -0.06451 0.008825" quat="0.5 -0.5 -0.5 0.5" mesh="sts3215" material="sts3215_material"/>
          <!-- <geom type="mesh" class="collision" pos="0.10099 -0.06451 0.008825" quat="0.5 -0.5 -0.5 0.5" mesh="sts3215" material="sts3215_material"/> -->
          <!-- Part thigh1016_2 -->
          <geom type="mesh" class="visual" pos="-0.03 1.38778e-17 -0.031175" quat="6.91522e-15 -1 0 -1.93385e-31" mesh="thigh1016" material="thigh1016_material"/>
          <!-- <geom type="mesh" class="collision" pos="-0.03 1.38778e-17 -0.031175" quat="6.91522e-15 -1 0 -1.93385e-31" mesh="thigh1016" material="thigh1016_material"/> -->
          <!-- Link knee_down_2 -->
          <body name="knee_down_2" pos="-0.02695 -5.41234e-16 0.018825" quat="0.707107 1.35793e-14 0.707107 1.15463e-14">
            <!-- Joint from low_hip_2 to knee_down_2 -->
            <joint axis="0 0 1" name="left_hip_yaw" type="hinge" range="-0.785 0.785" frictionloss="0.052" armature="0.028" damping="0"/>
            <inertial pos="-0.0107349 2.38445e-18 -0.0263596" mass="0.0153484" fullinertia="1.08234e-05 8.20048e-06 4.71676e-06 -4.277e-35 7.91036e-07 -2.00455e-36"/>
            <!-- Part knee_down_2 -->
            <geom type="mesh" class="visual" pos="0 0 -0.038" quat="0.707107 0.707107 0 1.06274e-30" mesh="knee_down" material="knee_down_material"/>
            <!-- <geom type="mesh" class="collision" pos="0 0 -0.038" quat="0.707107 0.707107 0 1.06274e-30" mesh="knee_down" material="knee_down_material"/> -->
            <!-- Link knee_2 -->
            <body name="knee_2" pos="6.93889e-18 -0.019 -0.059" quat="0.707107 0.707107 1.85407e-14 -1.97344e-14">
              <!-- Joint from knee_down_2 to knee_2 -->
              <joint axis="0 0 1" name="left_knee" type="hinge" range="-1.23 1.6" frictionloss="0.052" armature="0.028" damping="0"/>
              <inertial pos="-1.7237e-06 -0.0139003 -0.0179711" mass="0.0753846" fullinertia="3.1566e-05 1.85785e-05 2.44068e-05 8.05055e-09 2.14001e-09 -2.57668e-07"/>
              <!-- Part calf1016_2 -->
              <geom type="mesh" class="visual" pos="3.08781e-16 -0.05 -0.00305001" quat="0.5 0.5 -0.5 0.5" mesh="calf1016" material="calf1016_material"/>
              <!-- <geom type="mesh" class="collision" pos="3.08781e-16 -0.05 -0.00305001" quat="0.5 0.5 -0.5 0.5" mesh="calf1016" material="calf1016_material"/> -->
              <!-- Part sts3215_21 -->
              <geom type="mesh" class="visual" pos="-0.06451 -0.01 0.12794" quat="0 1 0 0" mesh="sts3215" material="sts3215_material"/>
              <!-- <geom type="mesh" class="collision" pos="-0.06451 -0.01 0.12794" quat="0 1 0 0" mesh="sts3215" material="sts3215_material"/> -->
              <!-- Link sts3215_2 -->
              <body name="sts3215_2" pos="3.1225e-16 -0.05 -0.000225009" quat="1 4.77396e-15 6.66134e-16 8.92342e-15">
                <!-- Joint from knee_2 to sts3215_2 -->
                <joint axis="0 0 1" name="left_ankle_pitch" type="hinge" frictionloss="0.052" armature="0.028" damping="0"/>
                <inertial pos="0.025324 -0.0124337 -0.0184974" mass="0.146992" fullinertia="4.7876e-05 0.000127593 0.000141039 -4.09568e-07 2.05493e-06 -1.35181e-07"/>
                <!-- Part sts3215_22 -->
                <geom type="mesh" class="visual" pos="-0.09499 -0.014834 0.04546" quat="0.707107 -1.23841e-14 0.707107 -3.71925e-15" mesh="sts3215" material="sts3215_material"/>
                <!-- <geom type="mesh" class="collision" pos="-0.09499 -0.014834 0.04546" quat="0.707107 -1.23841e-14 0.707107 -3.71925e-15" mesh="sts3215" material="sts3215_material"/> -->
                <!-- Part sts3215_23 -->
                <geom type="mesh" class="visual" pos="-0.06451 -0.01 0.12794" quat="0 1 0 0" mesh="sts3215" material="sts3215_material"/>
                <!-- <geom type="mesh" class="collision" pos="-0.06451 -0.01 0.12794" quat="0 1 0 0" mesh="sts3215" material="sts3215_material"/> -->
                <!-- Part left_ankle0120 -->
                <geom type="mesh" class="visual" pos="-1.249e-16 -0.035 -0.01905" quat="1.06581e-14 -1 5.4956e-15 6.02296e-15" mesh="left_ankle0120" material="left_ankle0120_material"/>
                <!-- <geom type="mesh" class="collision" pos="-1.249e-16 -0.035 -0.01905" quat="1.06581e-14 -1 5.4956e-15 6.02296e-15" mesh="left_ankle0120" material="left_ankle0120_material"/> -->
                <!-- Link left_foot0120 -->
                <body name="left_foot0120" pos="0.03295 -0.024834 -0.01905" quat="8.20373e-15 0.707107 7.77156e-15 0.707107">
                  <!-- Joint from sts3215_2 to left_foot0120 -->
                  <joint axis="0 0 1" name="left_ankle_roll" type="hinge" frictionloss="0.052" armature="0.028" damping="0"/>
                  <inertial pos="0.0154683 0.0283057 -0.0290094" mass="0.069069" fullinertia="0.000175929 0.000210947 4.03005e-05 -1.73185e-06 3.54868e-06 2.96376e-06"/>
                  <!-- Part left_foot0120 -->
                  <geom type="mesh" class="visual" pos="0.016 0.01 0.018825" quat="0.707107 0.707107 0 -2.79381e-31" mesh="left_foot0120" material="left_foot0120_material"/>
                  <!-- <geom type="mesh" class="collision" pos="0.016 0.01 0.018825" quat="0.707107 0.707107 0 -2.79381e-31" mesh="left_foot0120" material="left_foot0120_material"/> -->
                  <geom name="foot_collider_left" type="box" class="collision" pos="0.017 0.030 -0.033" size="0.04 0.005 0.09" material="collision_material"/>
                </body>
              </body>
            </body>
          </body>
        </body>
      </body>
    </body>
  </worldbody>
  <asset>
    <mesh file="leg_foundation1029.stl"/>
    <mesh file="right_foot0120.stl"/>
    <mesh file="elbow1216.stl"/>
    <mesh file="internal_weight_395g__configuration_default.stl"/>
    <mesh file="paw1018_left.stl"/>
    <mesh file="realsense_d435i.stl"/>
    <mesh file="left_foot0120.stl"/>
    <mesh file="deltoid.stl"/>
    <mesh file="paw1018.stl"/>
    <mesh file="hips1016.stl"/>
    <mesh file="head1209.stl"/>
    <mesh file="sts3215.stl"/>
    <mesh file="main_torso1204.stl"/>
    <mesh file="thumb1019.stl"/>
    <mesh file="thigh1016.stl"/>
    <mesh file="left_ankle0120.stl"/>
    <mesh file="calf1016.stl"/>
    <mesh file="knee_down.stl"/>
    <mesh file="shoulder1019.stl"/>
    <mesh file="right_ankle0120.stl"/>
    <material name="sts3215_material" rgba="0.4 0.4 0.4 1"/>
    <material name="main_torso1204_material" rgba="1 1 1 1"/>
    <material name="leg_foundation1029_material" rgba="1 1 1 1"/>
    <material name="internal_weight_395g__configuration_default_material" rgba="0.615686 0.811765 0.929412 1"/>
    <material name="head1209_material" rgba="1 1 1 1"/>
    <material name="realsense_d435i_material" rgba="0.866667 0.909804 1 1"/>
    <material name="shoulder1019_material" rgba="1 1 1 1"/>
    <material name="deltoid_material" rgba="1 1 1 1"/>
    <material name="elbow1216_material" rgba="1 1 1 1"/>
    <material name="paw1018_material" rgba="1 1 1 1"/>
    <material name="thumb1019_material" rgba="1 1 1 1"/>
    <material name="hips1016_material" rgba="1 1 1 1"/>
    <material name="thigh1016_material" rgba="1 1 1 1"/>
    <material name="knee_down_material" rgba="1 1 1 1"/>
    <material name="calf1016_material" rgba="1 1 1 1"/>
    <material name="right_ankle0120_material" rgba="0.717647 0.717647 0.717647 1"/>
    <material name="right_foot0120_material" rgba="0.717647 0.717647 0.717647 1"/>
    <material name="paw1018_left_material" rgba="1 1 1 1"/>
    <material name="left_ankle0120_material" rgba="0.717647 0.717647 0.717647 1"/>
    <material name="left_foot0120_material" rgba="0.717647 0.717647 0.717647 1"/>
    <material name="collision_material" rgba="1.0 0.28 0.1 0.9" />
  </asset>
  <actuator>
    <motor class="SundayA1_Mujoco" name="head_yaw" joint="head_yaw"/>
    <motor class="SundayA1_Mujoco" name="right_shoulder_pitch" joint="right_shoulder_pitch"/>
    <motor class="SundayA1_Mujoco" name="right_shoulder_yaw" joint="right_shoulder_yaw"/>
    <motor class="SundayA1_Mujoco" name="right_elbow" joint="right_elbow"/>
    <motor class="SundayA1_Mujoco" name="right_wrist" joint="right_wrist"/>
    <motor class="SundayA1_Mujoco" name="right_hand" joint="right_hand"/>
    <motor class="SundayA1_Mujoco" name="right_hip_roll" joint="right_hip_roll"/>
    <motor class="SundayA1_Mujoco" name="right_hip_pitch" joint="right_hip_pitch"/>
    <motor class="SundayA1_Mujoco" name="right_hip_yaw" joint="right_hip_yaw"/>
    <motor class="SundayA1_Mujoco" name="right_knee" joint="right_knee"/>
    <motor class="SundayA1_Mujoco" name="right_ankle_pitch" joint="right_ankle_pitch"/>
    <motor class="SundayA1_Mujoco" name="right_ankle_roll" joint="right_ankle_roll"/>
    <motor class="SundayA1_Mujoco" name="left_shoulder_pitch" joint="left_shoulder_pitch"/>
    <motor class="SundayA1_Mujoco" name="left_shoulder_roll" joint="left_shoulder_roll"/>
    <motor class="SundayA1_Mujoco" name="left_elbow" joint="left_elbow"/>
    <motor class="SundayA1_Mujoco" name="left_wrist" joint="left_wrist"/>
    <motor class="SundayA1_Mujoco" name="left_hand" joint="left_hand"/>
    <motor class="SundayA1_Mujoco" name="left_hip_roll" joint="left_hip_roll"/>
    <motor class="SundayA1_Mujoco" name="left_hip_pitch" joint="left_hip_pitch"/>
    <motor class="SundayA1_Mujoco" name="left_hip_yaw" joint="left_hip_yaw"/>
    <motor class="SundayA1_Mujoco" name="left_knee" joint="left_knee"/>
    <motor class="SundayA1_Mujoco" name="left_ankle_pitch" joint="left_ankle_pitch"/>
    <motor class="SundayA1_Mujoco" name="left_ankle_roll" joint="left_ankle_roll"/>
  </actuator>
  <equality/>
</mujoco>
