<?xml version="1.0" ?>
<robot name="SundayA1_Mujoco">
	<link name="base">
		<inertial>
			<origin rpy="0.00000 -0.00000 0.00000" xyz="0.00003 0.05756 0.05371"/>
			<mass value="0.46085"/>
			<inertia ixx="0.00000" ixy="0" ixz="0" iyy="0.00000" iyz="0" izz="0.00000"/>
		</inertial>
	</link>
	<link name="link0_2">
		<inertial>
			<origin rpy="0.00000 -0.00000 0.00000" xyz="0.00000 0.00000 0.00000"/>
			<mass value="0.00000"/>
			<inertia ixx="0.00000" ixy="0" ixz="0" iyy="0.00000" iyz="0" izz="0.00000"/>
		</inertial>
	</link>
	<link name="hip">
		<inertial>
			<origin rpy="0.00000 -0.00000 0.00000" xyz="0.00107 -0.03593 0.01882"/>
			<mass value="0.07622"/>
			<inertia ixx="0.00000" ixy="0" ixz="0" iyy="0.00000" iyz="0" izz="0.00000"/>
		</inertial>
	</link>
	<link name="link0_4">
		<inertial>
			<origin rpy="0.00000 -0.00000 0.00000" xyz="0.00000 0.00000 0.00000"/>
			<mass value="0.00000"/>
			<inertia ixx="0.00000" ixy="0" ixz="0" iyy="0.00000" iyz="0" izz="0.00000"/>
		</inertial>
	</link>
	<link name="low_hip">
		<inertial>
			<origin rpy="0.00000 -0.00000 0.00000" xyz="-0.04174 -0.00000 0.00770"/>
			<mass value="0.07814"/>
			<inertia ixx="0.00000" ixy="0" ixz="0" iyy="0.00000" iyz="0" izz="0.00000"/>
		</inertial>
	</link>
	<link name="link0_6">
		<inertial>
			<origin rpy="0.00000 -0.00000 0.00000" xyz="0.00000 0.00000 0.00000"/>
			<mass value="0.00000"/>
			<inertia ixx="0.00000" ixy="0" ixz="0" iyy="0.00000" iyz="0" izz="0.00000"/>
		</inertial>
	</link>
	<link name="knee_down">
		<inertial>
			<origin rpy="0.00000 -0.00000 0.00000" xyz="-0.01073 -0.00000 -0.02636"/>
			<mass value="0.01535"/>
			<inertia ixx="0.00000" ixy="0" ixz="0" iyy="0.00000" iyz="0" izz="0.00000"/>
		</inertial>
	</link>
	<link name="link0_8">
		<inertial>
			<origin rpy="0.00000 -0.00000 0.00000" xyz="0.00000 0.00000 0.00000"/>
			<mass value="0.00000"/>
			<inertia ixx="0.00000" ixy="0" ixz="0" iyy="0.00000" iyz="0" izz="0.00000"/>
		</inertial>
	</link>
	<link name="knee">
		<inertial>
			<origin rpy="0.00000 -0.00000 0.00000" xyz="-0.00000 0.01390 0.01797"/>
			<mass value="0.07538"/>
			<inertia ixx="0.00000" ixy="0" ixz="0" iyy="0.00000" iyz="0" izz="0.00000"/>
		</inertial>
	</link>
	<link name="link0_10">
		<inertial>
			<origin rpy="0.00000 -0.00000 0.00000" xyz="0.00000 0.00000 0.00000"/>
			<mass value="0.00000"/>
			<inertia ixx="0.00000" ixy="0" ixz="0" iyy="0.00000" iyz="0" izz="0.00000"/>
		</inertial>
	</link>
	<link name="foot1016">
		<inertial>
			<origin rpy="0.00000 -0.00000 0.00000" xyz="0.00302 -0.01830 -0.01811"/>
			<mass value="0.08801"/>
			<inertia ixx="0.00002" ixy="0" ixz="0" iyy="0.00007" iyz="0" izz="0.00006"/>
		</inertial>
		<collision>
			<origin rpy="0.00000 -0.00000 0.00000" xyz="0.01500 -0.04400 -0.02000"/>
			<geometry>
				<box size="0.09000 0.01000 0.04600"/>
			</geometry>
		</collision>
	</link>
	<link name="link0_12">
		<inertial>
			<origin rpy="0.00000 -0.00000 0.00000" xyz="0.00000 0.00000 0.00000"/>
			<mass value="0.00000"/>
			<inertia ixx="0.00000" ixy="0" ixz="0" iyy="0.00000" iyz="0" izz="0.00000"/>
		</inertial>
	</link>
	<link name="hip_2">
		<inertial>
			<origin rpy="0.00000 -0.00000 0.00000" xyz="0.00107 -0.03593 0.01882"/>
			<mass value="0.07622"/>
			<inertia ixx="0.00000" ixy="0" ixz="0" iyy="0.00000" iyz="0" izz="0.00000"/>
		</inertial>
	</link>
	<link name="link0_14">
		<inertial>
			<origin rpy="0.00000 -0.00000 0.00000" xyz="0.00000 0.00000 0.00000"/>
			<mass value="0.00000"/>
			<inertia ixx="0.00000" ixy="0" ixz="0" iyy="0.00000" iyz="0" izz="0.00000"/>
		</inertial>
	</link>
	<link name="low_hip_2">
		<inertial>
			<origin rpy="0.00000 -0.00000 0.00000" xyz="-0.04174 -0.00000 0.00770"/>
			<mass value="0.07814"/>
			<inertia ixx="0.00000" ixy="0" ixz="0" iyy="0.00000" iyz="0" izz="0.00000"/>
		</inertial>
	</link>
	<link name="link0_16">
		<inertial>
			<origin rpy="0.00000 -0.00000 0.00000" xyz="0.00000 0.00000 0.00000"/>
			<mass value="0.00000"/>
			<inertia ixx="0.00000" ixy="0" ixz="0" iyy="0.00000" iyz="0" izz="0.00000"/>
		</inertial>
	</link>
	<link name="knee_down_2">
		<inertial>
			<origin rpy="0.00000 -0.00000 0.00000" xyz="-0.01073 -0.00000 -0.02636"/>
			<mass value="0.01535"/>
			<inertia ixx="0.00000" ixy="0" ixz="0" iyy="0.00000" iyz="0" izz="0.00000"/>
		</inertial>
	</link>
	<link name="link0_18">
		<inertial>
			<origin rpy="0.00000 -0.00000 0.00000" xyz="0.00000 0.00000 0.00000"/>
			<mass value="0.00000"/>
			<inertia ixx="0.00000" ixy="0" ixz="0" iyy="0.00000" iyz="0" izz="0.00000"/>
		</inertial>
	</link>
	<link name="knee_2">
		<inertial>
			<origin rpy="0.00000 -0.00000 0.00000" xyz="-0.00000 -0.01390 -0.01797"/>
			<mass value="0.07538"/>
			<inertia ixx="0.00000" ixy="0" ixz="0" iyy="0.00000" iyz="0" izz="0.00000"/>
		</inertial>
	</link>
	<link name="link0_20">
		<inertial>
			<origin rpy="0.00000 -0.00000 0.00000" xyz="0.00000 0.00000 0.00000"/>
			<mass value="0.00000"/>
			<inertia ixx="0.00000" ixy="0" ixz="0" iyy="0.00000" iyz="0" izz="0.00000"/>
		</inertial>
	</link>
	<link name="foot1016_2">
		<inertial>
			<origin rpy="0.00000 -0.00000 0.00000" xyz="-0.00302 -0.01886 -0.01812"/>
			<mass value="0.08801"/>
			<inertia ixx="0.00002" ixy="0" ixz="0" iyy="0.00007" iyz="0" izz="0.00006"/>
		</inertial>
		<collision>
			<origin rpy="0.00000 -0.00000 0.00000" xyz="-0.01500 -0.04400 -0.02000"/>
			<geometry>
				<box size="0.09000 0.01000 0.04600"/>
			</geometry>
		</collision>
	</link>
	<joint name="right_hip_roll" type="continuous">
		<parent link="base"/>
		<child link="link0_2"/>
		<dynamics damping="1.0" friction="0.0001"/>
		<origin rpy="2.26893 0.00000 -1.57080" xyz="0.06187 0.05385 0.03348"/>
		<axis xyz="0.00000 0.00000 1.00000"/>
	</joint>
	<joint name="jointfix_4_2" type="fixed">
		<parent link="link0_2"/>
		<child link="hip"/>
		<dynamics damping="1.0" friction="0.0001"/>
		<origin rpy="0.00000 -0.00000 0.00000" xyz="0.00000 0.00000 0.00000"/>
		<axis xyz="0.00000 0.00000 0.00000"/>
	</joint>
	<joint name="right_hip_pitch" type="continuous">
		<parent link="hip"/>
		<child link="link0_4"/>
		<dynamics damping="1.0" friction="0.0001"/>
		<origin rpy="-1.57080 -0.00000 1.57080" xyz="0.01905 -0.05000 0.01883"/>
		<axis xyz="0.00000 0.00000 1.00000"/>
	</joint>
	<joint name="jointfix_3_4" type="fixed">
		<parent link="link0_4"/>
		<child link="low_hip"/>
		<dynamics damping="1.0" friction="0.0001"/>
		<origin rpy="0.00000 -0.00000 0.00000" xyz="0.00000 0.00000 0.00000"/>
		<axis xyz="0.00000 0.00000 0.00000"/>
	</joint>
	<joint name="right_hip_yaw" type="continuous">
		<parent link="low_hip"/>
		<child link="link0_6"/>
		<dynamics damping="1.0" friction="0.0001"/>
		<origin rpy="0.00000 1.57080 0.00000" xyz="-0.02695 0.00000 0.01883"/>
		<axis xyz="0.00000 0.00000 1.00000"/>
	</joint>
	<joint name="jointfix_2_6" type="fixed">
		<parent link="link0_6"/>
		<child link="knee_down"/>
		<dynamics damping="1.0" friction="0.0001"/>
		<origin rpy="0.00000 -0.00000 0.00000" xyz="0.00000 0.00000 0.00000"/>
		<axis xyz="0.00000 0.00000 0.00000"/>
	</joint>
	<joint name="right_knee" type="continuous">
		<parent link="knee_down"/>
		<child link="link0_8"/>
		<dynamics damping="1.0" friction="0.0001"/>
		<origin rpy="-1.57080 -0.00000 -3.14159" xyz="0.00000 0.01900 -0.05900"/>
		<axis xyz="0.00000 0.00000 1.00000"/>
	</joint>
	<joint name="jointfix_1_8" type="fixed">
		<parent link="link0_8"/>
		<child link="knee"/>
		<dynamics damping="1.0" friction="0.0001"/>
		<origin rpy="0.00000 -0.00000 0.00000" xyz="0.00000 0.00000 0.00000"/>
		<axis xyz="0.00000 0.00000 0.00000"/>
	</joint>
	<joint name="right_ankle" type="continuous">
		<parent link="knee"/>
		<child link="link0_10"/>
		<dynamics damping="1.0" friction="0.0001"/>
		<origin rpy="-3.14159 -0.00000 -0.00000" xyz="0.00000 0.05000 0.00023"/>
		<axis xyz="0.00000 0.00000 1.00000"/>
	</joint>
	<joint name="jointfix_0_10" type="fixed">
		<parent link="link0_10"/>
		<child link="foot1016"/>
		<dynamics damping="1.0" friction="0.0001"/>
		<origin rpy="0.00000 -0.00000 0.00000" xyz="0.00000 0.00000 0.00000"/>
		<axis xyz="0.00000 0.00000 0.00000"/>
	</joint>
	<joint name="left_hip_roll" type="continuous">
		<parent link="base"/>
		<child link="link0_12"/>
		<dynamics damping="1.0" friction="0.0001"/>
		<origin rpy="2.26893 -0.00000 1.57080" xyz="-0.06171 0.05385 0.03368"/>
		<axis xyz="0.00000 0.00000 1.00000"/>
	</joint>
	<joint name="jointfix_9_12" type="fixed">
		<parent link="link0_12"/>
		<child link="hip_2"/>
		<dynamics damping="1.0" friction="0.0001"/>
		<origin rpy="0.00000 -0.00000 0.00000" xyz="0.00000 0.00000 0.00000"/>
		<axis xyz="0.00000 0.00000 0.00000"/>
	</joint>
	<joint name="left_hip_pitch" type="continuous">
		<parent link="hip_2"/>
		<child link="link0_14"/>
		<dynamics damping="1.0" friction="0.0001"/>
		<origin rpy="1.57080 -0.00000 1.57080" xyz="-0.01860 -0.05000 0.01883"/>
		<axis xyz="0.00000 0.00000 1.00000"/>
	</joint>
	<joint name="jointfix_8_14" type="fixed">
		<parent link="link0_14"/>
		<child link="low_hip_2"/>
		<dynamics damping="1.0" friction="0.0001"/>
		<origin rpy="0.00000 -0.00000 0.00000" xyz="0.00000 0.00000 0.00000"/>
		<axis xyz="0.00000 0.00000 0.00000"/>
	</joint>
	<joint name="left_hip_yaw" type="continuous">
		<parent link="low_hip_2"/>
		<child link="link0_16"/>
		<dynamics damping="1.0" friction="0.0001"/>
		<origin rpy="0.00000 1.57080 -0.00000" xyz="-0.02695 0.00000 0.01883"/>
		<axis xyz="0.00000 0.00000 1.00000"/>
	</joint>
	<joint name="jointfix_7_16" type="fixed">
		<parent link="link0_16"/>
		<child link="knee_down_2"/>
		<dynamics damping="1.0" friction="0.0001"/>
		<origin rpy="0.00000 -0.00000 0.00000" xyz="0.00000 0.00000 0.00000"/>
		<axis xyz="0.00000 0.00000 0.00000"/>
	</joint>
	<joint name="left_knee" type="continuous">
		<parent link="knee_down_2"/>
		<child link="link0_18"/>
		<dynamics damping="1.0" friction="0.0001"/>
		<origin rpy="1.57080 0.00000 -0.00000" xyz="0.00000 -0.01900 -0.05900"/>
		<axis xyz="0.00000 0.00000 1.00000"/>
	</joint>
	<joint name="jointfix_6_18" type="fixed">
		<parent link="link0_18"/>
		<child link="knee_2"/>
		<dynamics damping="1.0" friction="0.0001"/>
		<origin rpy="0.00000 -0.00000 0.00000" xyz="0.00000 0.00000 0.00000"/>
		<axis xyz="0.00000 0.00000 0.00000"/>
	</joint>
	<joint name="left_ankle" type="continuous">
		<parent link="knee_2"/>
		<child link="link0_20"/>
		<dynamics damping="1.0" friction="0.0001"/>
		<origin rpy="0.00000 0.00000 0.00000" xyz="0.00000 -0.05000 -0.00023"/>
		<axis xyz="0.00000 0.00000 1.00000"/>
	</joint>
	<joint name="jointfix_5_20" type="fixed">
		<parent link="link0_20"/>
		<child link="foot1016_2"/>
		<dynamics damping="1.0" friction="0.0001"/>
		<origin rpy="0.00000 -0.00000 0.00000" xyz="0.00000 0.00000 0.00000"/>
		<axis xyz="0.00000 0.00000 0.00000"/>
	</joint>
</robot>
