<?xml version="1.0" ?>
<!-- Generated using onshape-to-robot -->
<!-- Onshape https://cad.onshape.com/documents/75898e4f36dccdb8f47bca25/w/e47b7562b7a7768436f44aef/e/ba58a3f077f6fae09dbedcba -->
<mujoco model="SundayA1_Mujoco">
  <compiler angle="radian" meshdir="assets" autolimits="true"/>
  <default>
    <default class="SundayA1_Mujoco">
      <joint frictionloss="0.1" armature="0.005"/>
      <position kp="50" dampratio="1"/>
      <default class="visual">
        <geom type="mesh" contype="0" conaffinity="0" group="2"/>
      </default>
      <default class="collision">
        <geom group="3"/>
      </default>
    </default>
  </default>
  <worldbody>
    <!-- Link body -->
    <body name="body" pos="0 0 0" quat="1 0 0 0" childclass="SundayA1_Mujoco">
      <freejoint name="body_freejoint"/>
      <inertial pos="-1.6949e-08 0.0488643 0.0348685" mass="0.919437" fullinertia="0.00340985 0.0045585 0.0026209 8.0934e-10 3.16401e-06 -0.000216638"/>
      <!-- Part leg_foundation -->
      <geom type="mesh" class="visual" pos="-0.0245693 0.0466603 -0.0314571" quat="0.241845 0.664463 -0.664463 -0.241845" mesh="leg_foundation" material="leg_foundation_material"/>
      <geom type="mesh" class="collision" pos="-0.0245693 0.0466603 -0.0314571" quat="0.241845 0.664463 -0.664463 -0.241845" mesh="leg_foundation" material="leg_foundation_material"/>
      <!-- Part sts3250 -->
      <geom type="mesh" class="visual" pos="0.150026 0.11117 0.0477053" quat="0.298836 0.640856 -0.640856 -0.298836" mesh="sts3250" material="sts3250_material"/>
      <geom type="mesh" class="collision" pos="0.150026 0.11117 0.0477053" quat="0.298836 0.640856 -0.640856 -0.298836" mesh="sts3250" material="sts3250_material"/>
      <!-- Part torso_short0212 -->
      <geom type="mesh" class="visual" pos="-3.65721e-18 0.0466603 0.035" quat="3.42114e-49 0 0 -1" mesh="torso_short0212" material="torso_short0212_material"/>
      <geom type="mesh" class="collision" pos="-3.65721e-18 0.0466603 0.035" quat="3.42114e-49 0 0 -1" mesh="torso_short0212" material="torso_short0212_material"/>
      <!-- Part leg_adapter -->
      <geom type="mesh" class="visual" pos="-0.0323 0.0466603 -0.008" quat="0.707107 0.707107 0 3.69434e-17" mesh="leg_adapter" material="leg_adapter_material"/>
      <geom type="mesh" class="collision" pos="-0.0323 0.0466603 -0.008" quat="0.707107 0.707107 0 3.69434e-17" mesh="leg_adapter" material="leg_adapter_material"/>
      <!-- Part leg_foundation_2 -->
      <geom type="mesh" class="visual" pos="0.0245693 0.0466603 -0.0314571" quat="0.241845 0.664463 0.664463 0.241845" mesh="leg_foundation" material="leg_foundation_material"/>
      <geom type="mesh" class="collision" pos="0.0245693 0.0466603 -0.0314571" quat="0.241845 0.664463 0.664463 0.241845" mesh="leg_foundation" material="leg_foundation_material"/>
      <!-- Part sts3250_2 -->
      <geom type="mesh" class="visual" pos="-0.150026 -0.0178497 0.0477053" quat="0.298836 0.640856 0.640856 0.298836" mesh="sts3250" material="sts3250_material"/>
      <geom type="mesh" class="collision" pos="-0.150026 -0.0178497 0.0477053" quat="0.298836 0.640856 0.640856 0.298836" mesh="sts3250" material="sts3250_material"/>
      <!-- Part sts3215 -->
      <geom type="mesh" class="visual" pos="0.06451 0.0548603 0.26339" quat="1.80348e-16 -0 1 0" mesh="sts3215" material="sts3215_material"/>
      <geom type="mesh" class="collision" pos="0.06451 0.0548603 0.26339" quat="1.80348e-16 -0 1 0" mesh="sts3215" material="sts3215_material"/>
      <!-- Part leg_adapter_2 -->
      <geom type="mesh" class="visual" pos="0.0323 0.0466603 -0.008" quat="3.69434e-17 -0 0.707107 0.707107" mesh="leg_adapter" material="leg_adapter_material"/>
      <geom type="mesh" class="collision" pos="0.0323 0.0466603 -0.008" quat="3.69434e-17 -0 0.707107 0.707107" mesh="leg_adapter" material="leg_adapter_material"/>
      <!-- Part sts3215_2 -->
      <geom type="mesh" class="visual" pos="-0.21099 0.11117 0.082" quat="0.5 -0.5 0.5 -0.5" mesh="sts3215" material="sts3215_material"/>
      <geom type="mesh" class="collision" pos="-0.21099 0.11117 0.082" quat="0.5 -0.5 0.5 -0.5" mesh="sts3215" material="sts3215_material"/>
      <!-- Part internal_weight_395g__configuration_default -->
      <geom type="mesh" class="visual" pos="0.0357255 0.0793234 0.05" quat="0 -1.60056e-16 -1 1.94933e-16" mesh="internal_weight_395g__configuration_default" material="internal_weight_395g__configuration_default_material"/>
      <geom type="mesh" class="collision" pos="0.0357255 0.0793234 0.05" quat="0 -1.60056e-16 -1 1.94933e-16" mesh="internal_weight_395g__configuration_default" material="internal_weight_395g__configuration_default_material"/>
      <!-- Part sts3215_3 -->
      <geom type="mesh" class="visual" pos="0.21099 -0.0178497 0.081254" quat="0.5 -0.5 -0.5 0.5" mesh="sts3215" material="sts3215_material"/>
      <geom type="mesh" class="collision" pos="0.21099 -0.0178497 0.081254" quat="0.5 -0.5 -0.5 0.5" mesh="sts3215" material="sts3215_material"/>
      <!-- Link head1209 -->
      <body name="head1209" pos="-2.67391e-17 0.0448603 0.13545" quat="2.36526e-27 -0.00230208 0.999997 -2.55859e-26">
        <!-- Joint from body to head1209 -->
        <joint axis="0 0 1" name="head_yaw" type="hinge" range="-1 1" frictionloss="0.052" armature="0.028" damping="0"/>
        <inertial pos="0 0 0" mass="1e-09" fullinertia="1e-09 1e-09 1e-09 0 0 0"/>
        <!-- Part max4466 -->
        <geom type="mesh" class="visual" pos="-0.0090644 0.01609 -0.0636732" quat="0.707107 0.707107 -1.11022e-16 6.46078e-17" mesh="max4466" material="max4466_material"/>
        <geom type="mesh" class="collision" pos="-0.0090644 0.01609 -0.0636732" quat="0.707107 0.707107 -1.11022e-16 6.46078e-17" mesh="max4466" material="max4466_material"/>
        <!-- Part realsense_d435i -->
        <geom type="mesh" class="visual" pos="-1.85941e-17 0.00146458 -0.0981134" quat="0.866025 -0.5 -0 -6.14787e-17" mesh="realsense_d435i" material="realsense_d435i_material"/>
        <geom type="mesh" class="collision" pos="-1.85941e-17 0.00146458 -0.0981134" quat="0.866025 -0.5 -0 -6.14787e-17" mesh="realsense_d435i" material="realsense_d435i_material"/>
        <!-- Part max4466_2 -->
        <geom type="mesh" class="visual" pos="0.00885766 0.01609 -0.0313509" quat="1.11022e-16 -2.3127e-16 -0.707107 0.707107" mesh="max4466__2" material="max4466__2_material"/>
        <geom type="mesh" class="collision" pos="0.00885766 0.01609 -0.0313509" quat="1.11022e-16 -2.3127e-16 -0.707107 0.707107" mesh="max4466__2" material="max4466__2_material"/>
        <!-- Part head1209 -->
        <geom type="mesh" class="visual" pos="-1.5992e-17 0.0225 -0.09" quat="1.7298e-36 1 1.36694e-19 8.88178e-17" mesh="head1209" material="head1209_material"/>
        <geom type="mesh" class="collision" pos="-1.5992e-17 0.0225 -0.09" quat="1.7298e-36 1 1.36694e-19 8.88178e-17" mesh="head1209" material="head1209_material"/>
        <!-- Part max4466_3 -->
        <geom type="mesh" class="visual" pos="0.00885766 0.01609 -0.0313509" quat="1.11022e-16 -2.3127e-16 -0.707107 0.707107" mesh="max4466__3" material="max4466__3_material"/>
        <geom type="mesh" class="collision" pos="0.00885766 0.01609 -0.0313509" quat="1.11022e-16 -2.3127e-16 -0.707107 0.707107" mesh="max4466__3" material="max4466__3_material"/>
      </body>
      <!-- Link shoulder -->
      <body name="shoulder" pos="0.08305 0.0466603 0.091254" quat="0.5 0.5 0.5 0.5">
        <!-- Joint from body to shoulder -->
        <joint axis="0 0 1" name="right_shoulder_pitch" type="hinge" range="-0.785 0.785" frictionloss="0.052" armature="0.028" damping="0"/>
        <inertial pos="-7.74179e-08 0.0146453 0.00369943" mass="0.0259955" fullinertia="2.22226e-05 2.49882e-05 5.15337e-06 -3.73679e-12 -5.71921e-11 -1.99158e-08"/>
        <!-- Part shoulder0219 -->
        <geom type="mesh" class="visual" pos="6.93889e-18 1.38778e-17 1.38778e-17" quat="0.5 -0.5 0.5 -0.5" mesh="shoulder0219" material="shoulder0219_material"/>
        <geom type="mesh" class="collision" pos="6.93889e-18 1.38778e-17 1.38778e-17" quat="0.5 -0.5 0.5 -0.5" mesh="shoulder0219" material="shoulder0219_material"/>
        <!-- Link sts3215 -->
        <body name="sts3215" pos="0.019 0.01 0.049" quat="0.5 -0.5 0.5 -0.5">
          <!-- Joint from shoulder to sts3215 -->
          <joint axis="0 0 1" name="right_shoulder_roll" type="hinge" range="-1.7 1.7" frictionloss="0.052" armature="0.028" damping="0"/>
          <inertial pos="0.0396149 -1.73498e-06 -0.0251363" mass="0.149789" fullinertia="4.79732e-05 0.000171303 0.000148054 -5.66256e-09 2.71954e-05 1.01133e-08"/>
          <!-- Part tricep0219 -->
          <geom type="mesh" class="visual" pos="0.026159 2.22045e-16 -0.01905" quat="0.5 -0.5 0.5 -0.5" mesh="tricep0219" material="tricep0219_material"/>
          <geom type="mesh" class="collision" pos="0.026159 2.22045e-16 -0.01905" quat="0.5 -0.5 0.5 -0.5" mesh="tricep0219" material="tricep0219_material"/>
          <!-- Part sts3215_4 -->
          <geom type="mesh" class="visual" pos="0.213149 -0.06451 -0.028996" quat="0.5 -0.5 -0.5 0.5" mesh="sts3215" material="sts3215_material"/>
          <geom type="mesh" class="collision" pos="0.213149 -0.06451 -0.028996" quat="0.5 -0.5 -0.5 0.5" mesh="sts3215" material="sts3215_material"/>
          <!-- Part sts3215_5 -->
          <geom type="mesh" class="visual" pos="0.01 -0.06451 0.12794" quat="5.82387e-32 -0.707107 -0.707107 3.99513e-32" mesh="sts3215" material="sts3215_material"/>
          <geom type="mesh" class="collision" pos="0.01 -0.06451 0.12794" quat="5.82387e-32 -0.707107 -0.707107 3.99513e-32" mesh="sts3215" material="sts3215_material"/>
          <!-- Link bicep0215 -->
          <body name="bicep0215" pos="0.047559 -2.77556e-17 -0.018996" quat="0.5 0.5 0.5 0.5">
            <!-- Joint from sts3215 to bicep0215 -->
            <joint axis="0 0 1" name="right_shoulder_yaw" type="hinge" frictionloss="0.052" armature="0.028" damping="0"/>
            <inertial pos="-3.43692e-08 0.0105064 0.0304454" mass="0.0164132" fullinertia="9.00476e-06 1.06984e-05 4.20346e-06 -2.27858e-12 -2.22701e-11 8.80917e-07"/>
            <!-- Part bicep0215 -->
            <geom type="mesh" class="visual" pos="0 0 0.038" quat="0.5 -0.5 0.5 -0.5" mesh="bicep0215" material="bicep0215_material"/>
            <geom type="mesh" class="collision" pos="0 0 0.038" quat="0.5 -0.5 0.5 -0.5" mesh="bicep0215" material="bicep0215_material"/>
            <!-- Link right_wrist0124 -->
            <body name="right_wrist0124" pos="-0.019 -1.01308e-15 0.059" quat="0.5 -0.5 -0.5 0.5">
              <!-- Joint from bicep0215 to right_wrist0124 -->
              <joint axis="0 0 1" name="right_elbow_pitch" type="hinge" frictionloss="0.052" armature="0.028" damping="0"/>
              <inertial pos="-0.00672825 -0.039208 -0.0185055" mass="0.149081" fullinertia="0.000152342 4.52601e-05 0.000162039 -2.32758e-05 -5.5014e-07 -2.30887e-06"/>
              <!-- Part sts3215_6 -->
              <geom type="mesh" class="visual" pos="-0.06451 -0.01 0.12794" quat="0 1 0 0" mesh="sts3215" material="sts3215_material"/>
              <geom type="mesh" class="collision" pos="-0.06451 -0.01 0.12794" quat="0 1 0 0" mesh="sts3215" material="sts3215_material"/>
              <!-- Part right_wrist0124 -->
              <geom type="mesh" class="visual" pos="1.38778e-17 -0.026159 -0.01905" quat="0.5 0.5 -0.5 0.5" mesh="right_wrist0124" material="right_wrist0124_material"/>
              <geom type="mesh" class="collision" pos="1.38778e-17 -0.026159 -0.01905" quat="0.5 0.5 -0.5 0.5" mesh="right_wrist0124" material="right_wrist0124_material"/>
              <!-- Part sts3215_7 -->
              <geom type="mesh" class="visual" pos="-0.01 -0.213149 0.04546" quat="0.5 -0.5 0.5 0.5" mesh="sts3215" material="sts3215_material"/>
              <geom type="mesh" class="collision" pos="-0.01 -0.213149 0.04546" quat="0.5 -0.5 0.5 0.5" mesh="sts3215" material="sts3215_material"/>
              <!-- Link right_hand -->
              <body name="right_hand" pos="5.55112e-17 -0.085209 -0.01905" quat="0.5 -0.5 0.5 0.5">
                <!-- Joint from right_wrist0124 to right_hand -->
                <joint axis="0 0 1" name="right_wrist_yaw" type="hinge" frictionloss="0.052" armature="0.028" damping="0"/>
                <inertial pos="-0.000729897 -0.00113781 -0.0212412" mass="0.107683" fullinertia="7.60984e-05 7.06376e-05 3.80343e-05 -9.19788e-08 -5.77082e-07 1.24624e-05"/>
                <!-- Part sts3215_8 -->
                <geom type="mesh" class="visual" pos="-0.14699 -0.002554 0.03651" quat="0.707107 2.07633e-14 0.707107 -2.12261e-14" mesh="sts3215" material="sts3215_material"/>
                <geom type="mesh" class="collision" pos="-0.14699 -0.002554 0.03651" quat="0.707107 2.07633e-14 0.707107 -2.12261e-14" mesh="sts3215" material="sts3215_material"/>
                <!-- Part right_paw0215 -->
                <geom type="mesh" class="visual" pos="-0.016 9.64506e-16 -0.025" quat="1.04083e-17 -2.96829e-14 -1 3.22583e-16" mesh="right_paw0215" material="right_paw0215_material"/>
                <geom type="mesh" class="collision" pos="-0.016 9.64506e-16 -0.025" quat="1.04083e-17 -2.96829e-14 -1 3.22583e-16" mesh="right_paw0215" material="right_paw0215_material"/>
                <!-- Link thumb_0112 -->
                <body name="thumb_0112" pos="-0.01905 -0.012554 -0.028" quat="2.07487e-14 -0.707107 2.12053e-14 0.707107">
                  <!-- Joint from right_hand to thumb_0112 -->
                  <joint axis="0 0 1" name="right_hand" type="hinge" range="-2.5 0" frictionloss="0.052" armature="0.028" damping="0"/>
                  <inertial pos="0.0270123 -0.00215478 -0.018825" mass="0.0051587" fullinertia="8.61073e-07 2.19119e-06 1.56579e-06 2.48224e-07 4.40556e-15 1.59335e-14"/>
                  <!-- Part thumb_0112 -->
                  <geom type="mesh" class="visual" pos="-1.38778e-17 0 -0.018825" quat="0.514251 -0.514251 0.485331 -0.485331" mesh="thumb_0112" material="thumb_0112_material"/>
                  <geom type="mesh" class="collision" pos="-1.38778e-17 0 -0.018825" quat="0.514251 -0.514251 0.485331 -0.485331" mesh="thumb_0112" material="thumb_0112_material"/>
                </body>
              </body>
            </body>
          </body>
        </body>
      </body>
      <!-- Link hip -->
      <body name="hip" pos="0.0584461 0.0466603 -0.0421933" quat="0.298836 0.640856 -0.640856 -0.298836">
        <!-- Joint from body to hip -->
        <joint axis="0 0 1" name="right_hip_roll" type="hinge" range="-1 1" frictionloss="0.052" armature="0.028" damping="0"/>
        <inertial pos="0.0010905 -0.0362656 0.0188233" mass="0.0855956" fullinertia="2.91207e-05 2.11816e-05 3.40671e-05 2.71351e-07 2.44685e-09 -9.18667e-09"/>
        <!-- Part sts3250_3 -->
        <geom type="mesh" class="visual" pos="0.14699 -0.04 -0.045685" quat="0.707107 6.63065e-15 -0.707107 -6.99441e-15" mesh="sts3250" material="sts3250_material"/>
        <geom type="mesh" class="collision" pos="0.14699 -0.04 -0.045685" quat="0.707107 6.63065e-15 -0.707107 -6.99441e-15" mesh="sts3250" material="sts3250_material"/>
        <!-- Part hips1016 -->
        <geom type="mesh" class="visual" pos="0.016 0 0.018825" quat="0.707107 -0.707107 -0 4.51052e-32" mesh="hips1016" material="hips1016_material"/>
        <geom type="mesh" class="collision" pos="0.016 0 0.018825" quat="0.707107 -0.707107 -0 4.51052e-32" mesh="hips1016" material="hips1016_material"/>
        <!-- Link low_hip -->
        <body name="low_hip" pos="0.01905 -0.05 0.018825" quat="0.298836 -0.640856 -0.298836 0.640856">
          <!-- Joint from hip to low_hip -->
          <joint axis="0 0 1" name="right_hip_pitch" type="hinge" range="-1.6 1.6" frictionloss="0.052" armature="0.028" damping="0"/>
          <inertial pos="-0.040824 -1.59298e-06 0.00773057" mass="0.0933278" fullinertia="2.8675e-05 4.55973e-05 3.05392e-05 1.83928e-09 -3.21234e-06 8.78737e-09"/>
          <!-- Part sts3250_4 -->
          <geom type="mesh" class="visual" pos="0.10099 -0.06451 0.008825" quat="0.5 -0.5 -0.5 0.5" mesh="sts3250" material="sts3250_material"/>
          <geom type="mesh" class="collision" pos="0.10099 -0.06451 0.008825" quat="0.5 -0.5 -0.5 0.5" mesh="sts3250" material="sts3250_material"/>
          <!-- Part thigh1111 -->
          <geom type="mesh" class="visual" pos="-0.03 0 -0.031175" quat="6.91522e-15 -1 0 -4.06781e-32" mesh="thigh1111" material="thigh1111_material"/>
          <geom type="mesh" class="collision" pos="-0.03 0 -0.031175" quat="6.91522e-15 -1 0 -4.06781e-32" mesh="thigh1111" material="thigh1111_material"/>
          <!-- Link knee_down -->
          <body name="knee_down" pos="-0.02695 -3.747e-16 0.018825" quat="0.707107 1.25892e-14 0.707107 1.29896e-14">
            <!-- Joint from low_hip to knee_down -->
            <joint axis="0 0 1" name="right_hip_yaw" type="hinge" range="-0.785 0.785" frictionloss="0.052" armature="0.028" damping="0"/>
            <inertial pos="-0.0107349 2.97228e-18 -0.0263596" mass="0.0153484" fullinertia="1.08234e-05 8.20048e-06 4.71676e-06 -2.9532e-35 7.91036e-07 -2.30105e-36"/>
            <!-- Part knee_down -->
            <geom type="mesh" class="visual" pos="0 0 -0.038" quat="0.707107 0.707107 0 -8.4174e-32" mesh="knee_down" material="knee_down_material"/>
            <geom type="mesh" class="collision" pos="0 0 -0.038" quat="0.707107 0.707107 0 -8.4174e-32" mesh="knee_down" material="knee_down_material"/>
            <!-- Link knee -->
            <body name="knee" pos="1.38778e-17 0.019 -0.059" quat="1.11022e-16 7.38429e-17 -0.707107 0.707107">
              <!-- Joint from knee_down to knee -->
              <joint axis="0 0 1" name="right_knee" type="hinge" range="-1.23 1.6" frictionloss="0.052" armature="0.028" damping="0"/>
              <inertial pos="-1.6645e-06 0.014753 0.0180095" mass="0.089322" fullinertia="4.06015e-05 2.34719e-05 3.03909e-05 -9.3381e-09 -2.45428e-09 -3.70177e-07"/>
              <!-- Part calf1028 -->
              <geom type="mesh" class="visual" pos="3.88578e-16 0.0500539 0.00305001" quat="0.5 -0.5 0.5 0.5" mesh="calf1028" material="calf1028_material"/>
              <geom type="mesh" class="collision" pos="3.88578e-16 0.0500539 0.00305001" quat="0.5 -0.5 0.5 0.5" mesh="calf1028" material="calf1028_material"/>
              <!-- Part sts3250_5 -->
              <geom type="mesh" class="visual" pos="-0.06451 0.01 -0.12794" quat="1 -0 1.52656e-16 -8.32667e-17" mesh="sts3250" material="sts3250_material"/>
              <geom type="mesh" class="collision" pos="-0.06451 0.01 -0.12794" quat="1 -0 1.52656e-16 -8.32667e-17" mesh="sts3250" material="sts3250_material"/>
              <!-- Link sts3250 -->
              <body name="sts3250" pos="3.88578e-16 0.0500539 0.000225009" quat="1.28727e-15 -1 1.38778e-17 -2.21976e-15">
                <!-- Joint from knee to sts3250 -->
                <joint axis="0 0 1" name="right_ankle_pitch" type="hinge" frictionloss="0.052" armature="0.028" damping="0"/>
                <inertial pos="-0.0253308 -0.0124615 -0.0184902" mass="0.165746" fullinertia="5.39066e-05 0.000143783 0.000159117 -3.60844e-07 -2.35286e-06 -1.71457e-07"/>
                <!-- Part sts3250_6 -->
                <geom type="mesh" class="visual" pos="0.09499 -0.014888 -0.08356" quat="0.707107 -8.40375e-16 -0.707107 2.33147e-15" mesh="sts3250" material="sts3250_material"/>
                <geom type="mesh" class="collision" pos="0.09499 -0.014888 -0.08356" quat="0.707107 -8.40375e-16 -0.707107 2.33147e-15" mesh="sts3250" material="sts3250_material"/>
                <!-- Part sts3250_7 -->
                <geom type="mesh" class="visual" pos="-0.06451 -0.01 0.12794" quat="0 1 0 0" mesh="sts3250" material="sts3250_material"/>
                <geom type="mesh" class="collision" pos="-0.06451 -0.01 0.12794" quat="0 1 0 0" mesh="sts3250" material="sts3250_material"/>
                <!-- Part right_ankle0120 -->
                <geom type="mesh" class="visual" pos="1.38778e-17 -0.035054 -0.01905" quat="2.22045e-16 1.82984e-15 -1.44329e-15 -1" mesh="right_ankle0120" material="right_ankle0120_material"/>
                <geom type="mesh" class="collision" pos="1.38778e-17 -0.035054 -0.01905" quat="2.22045e-16 1.82984e-15 -1.44329e-15 -1" mesh="right_ankle0120" material="right_ankle0120_material"/>
                <!-- Link right_foot0120 -->
                <body name="right_foot0120" pos="-0.03295 -0.024888 -0.01905" quat="7.0304e-15 -0.707107 -8.43769e-15 0.707107">
                  <!-- Joint from sts3250 to right_foot0120 -->
                  <joint axis="0 0 1" name="right_ankle_roll" type="hinge" frictionloss="0.052" armature="0.028" damping="0"/>
                  <inertial pos="-0.015468 0.0283055 -0.0290089" mass="0.0697141" fullinertia="0.000177573 0.00021292 4.0677e-05 1.74827e-06 -3.58318e-06 2.99215e-06"/>
                  <!-- Part right_foot0120 -->
                  <geom type="mesh" class="visual" pos="-0.016 0.01 0.018825" quat="0.707107 0.707107 0 -6.59402e-31" mesh="right_foot0120" material="right_foot0120_material"/>
                  <geom type="mesh" class="collision" pos="-0.016 0.01 0.018825" quat="0.707107 0.707107 0 -6.59402e-31" mesh="right_foot0120" material="right_foot0120_material"/>
                </body>
              </body>
            </body>
          </body>
        </body>
      </body>
      <!-- Link shoulder_2 -->
      <body name="shoulder_2" pos="-0.08305 0.0466603 0.092" quat="0.5 -0.5 0.5 -0.5">
        <!-- Joint from body to shoulder_2 -->
        <joint axis="0 0 1" name="left_shoulder_pitch" type="hinge" range="-0.785 0.785" frictionloss="0.052" armature="0.028" damping="0"/>
        <inertial pos="-7.74179e-08 -0.0146453 -0.00369943" mass="0.0259955" fullinertia="2.22226e-05 2.49882e-05 5.15337e-06 3.73679e-12 5.71921e-11 -1.99158e-08"/>
        <!-- Part shoulder0219_2 -->
        <geom type="mesh" class="visual" pos="0 0 0" quat="0.5 0.5 0.5 0.5" mesh="shoulder0219" material="shoulder0219_material"/>
        <geom type="mesh" class="collision" pos="0 0 0" quat="0.5 0.5 0.5 0.5" mesh="shoulder0219" material="shoulder0219_material"/>
        <!-- Link sts3215_2 -->
        <body name="sts3215_2" pos="-0.019 -0.01 -0.049" quat="7.69521e-19 0.707107 -4.44089e-16 -0.707107">
          <!-- Joint from shoulder_2 to sts3215_2 -->
          <joint axis="0 0 1" name="left_shoulder_roll" type="hinge" range="-1.7 1.7" frictionloss="0.052" armature="0.028" damping="0"/>
          <inertial pos="-1.73498e-06 -0.0396149 -0.0251363" mass="0.149789" fullinertia="0.000171303 4.79732e-05 0.000148054 5.66256e-09 1.01133e-08 -2.71954e-05"/>
          <!-- Part sts3215_9 -->
          <geom type="mesh" class="visual" pos="-0.06451 -0.213149 -0.028996" quat="0.707107 -0.707107 1.88738e-15 -1.87247e-15" mesh="sts3215" material="sts3215_material"/>
          <geom type="mesh" class="collision" pos="-0.06451 -0.213149 -0.028996" quat="0.707107 -0.707107 1.88738e-15 -1.87247e-15" mesh="sts3215" material="sts3215_material"/>
          <!-- Part tricep0219_2 -->
          <geom type="mesh" class="visual" pos="1.94289e-16 -0.026159 -0.01905" quat="2.10942e-15 -1.89961e-15 -0.707107 0.707107" mesh="tricep0219" material="tricep0219_material"/>
          <geom type="mesh" class="collision" pos="1.94289e-16 -0.026159 -0.01905" quat="2.10942e-15 -1.89961e-15 -0.707107 0.707107" mesh="tricep0219" material="tricep0219_material"/>
          <!-- Part sts3215_10 -->
          <geom type="mesh" class="visual" pos="-0.06451 -0.01 0.12794" quat="0 1 0 0" mesh="sts3215" material="sts3215_material"/>
          <geom type="mesh" class="collision" pos="-0.06451 -0.01 0.12794" quat="0 1 0 0" mesh="sts3215" material="sts3215_material"/>
          <!-- Link bicep0215_2 -->
          <body name="bicep0215_2" pos="-4.16334e-16 -0.085209 -0.018996" quat="0.707107 -0.707107 1.88738e-15 -1.87247e-15">
            <!-- Joint from sts3215_2 to bicep0215_2 -->
            <joint axis="0 0 1" name="left_shoulder_yaw" type="hinge" frictionloss="0.052" armature="0.028" damping="0"/>
            <inertial pos="0.000838992 -0.0104729 0.00755461" mass="0.0164132" fullinertia="9.01556e-06 1.06876e-05 4.20346e-06 -1.34816e-07 -7.03264e-08 8.78105e-07"/>
            <!-- Part bicep0215_2 -->
            <geom type="mesh" class="visual" pos="0 0 0" quat="0.47962 0.47962 0.519581 0.519581" mesh="bicep0215" material="bicep0215_material"/>
            <geom type="mesh" class="collision" pos="0 0 0" quat="0.47962 0.47962 0.519581 0.519581" mesh="bicep0215" material="bicep0215_material"/>
            <!-- Link sts3215_3 -->
            <body name="sts3215_3" pos="0.0189393 0.00151731 -0.021" quat="0.47962 0.47962 0.519581 0.519581">
              <!-- Joint from bicep0215_2 to sts3215_3 -->
              <joint axis="0 0 1" name="left_elbow_pitch" type="hinge" frictionloss="0.052" armature="0.028" damping="0"/>
              <inertial pos="0.00670296 -0.039208 -0.0185072" mass="0.149081" fullinertia="0.000152342 4.52341e-05 0.000162013 2.31994e-05 5.38439e-07 -2.32039e-06"/>
              <!-- Part sts3215_11 -->
              <geom type="mesh" class="visual" pos="0.009946 -0.213149 -0.08356" quat="0.5 -0.5 -0.5 -0.5" mesh="sts3215" material="sts3215_material"/>
              <geom type="mesh" class="collision" pos="0.009946 -0.213149 -0.08356" quat="0.5 -0.5 -0.5 -0.5" mesh="sts3215" material="sts3215_material"/>
              <!-- Part left_wrist0124 -->
              <geom type="mesh" class="visual" pos="-4.92661e-16 -0.026159 -0.01905" quat="0.5 0.5 -0.5 0.5" mesh="left_wrist0124" material="left_wrist0124_material"/>
              <geom type="mesh" class="collision" pos="-4.92661e-16 -0.026159 -0.01905" quat="0.5 0.5 -0.5 0.5" mesh="left_wrist0124" material="left_wrist0124_material"/>
              <!-- Part sts3215_12 -->
              <geom type="mesh" class="visual" pos="-0.06451 -0.01 0.12794" quat="0 1 0 0" mesh="sts3215" material="sts3215_material"/>
              <geom type="mesh" class="collision" pos="-0.06451 -0.01 0.12794" quat="0 1 0 0" mesh="sts3215" material="sts3215_material"/>
              <!-- Link left_hand -->
              <body name="left_hand" pos="-5.4e-05 -0.085209 -0.01905" quat="0.5 -0.5 -0.5 -0.5">
                <!-- Joint from sts3215_3 to left_hand -->
                <joint axis="0 0 1" name="left_wrist_yaw" type="hinge" frictionloss="0.052" armature="0.028" damping="0"/>
                <inertial pos="0.000639307 -0.00115995 -0.0212436" mass="0.107683" fullinertia="7.60784e-05 7.06616e-05 3.80313e-05 -3.45493e-07 1.57548e-06 1.23844e-05"/>
                <!-- Part sts3215_13 -->
                <geom type="mesh" class="visual" pos="0.146321 -0.0142304 -0.09251" quat="0.706542 -0.0282568 -0.706542 -0.0282568" mesh="sts3215" material="sts3215_material"/>
                <geom type="mesh" class="collision" pos="0.146321 -0.0142304 -0.09251" quat="0.706542 -0.0282568 -0.706542 -0.0282568" mesh="sts3215" material="sts3215_material"/>
                <!-- Part left_paw0215 -->
                <geom type="mesh" class="visual" pos="0.0159489 -0.00127773 -0.025" quat="8.28229e-17 -0.999201 0.0399611 5.97082e-17" mesh="left_paw0215" material="left_paw0215_material"/>
                <geom type="mesh" class="collision" pos="0.0159489 -0.00127773 -0.025" quat="8.28229e-17 -0.999201 0.0399611 5.97082e-17" mesh="left_paw0215" material="left_paw0215_material"/>
                <!-- Link thumb_0112_2 -->
                <body name="thumb_0112_2" pos="0.0179909 -0.0139814 -0.028" quat="0.706542 -0.0282568 -0.706542 -0.0282568">
                  <!-- Joint from left_hand to thumb_0112_2 -->
                  <joint axis="0 0 1" name="left_hand" type="hinge" range="0 2.5" frictionloss="0.052" armature="0.028" damping="0"/>
                  <inertial pos="-0.0268425 0.00371289 0.018825" mass="0.0051587" fullinertia="8.94173e-07 2.15809e-06 1.56579e-06 3.23337e-07 -5.31938e-15 -1.56522e-14"/>
                  <!-- Part thumb_0112_2 -->
                  <geom type="mesh" class="visual" pos="0 2.08167e-17 0.018825" quat="0.5 -0.5 -0.5 0.5" mesh="thumb_0112" material="thumb_0112_material"/>
                  <geom type="mesh" class="collision" pos="0 2.08167e-17 0.018825" quat="0.5 -0.5 -0.5 0.5" mesh="thumb_0112" material="thumb_0112_material"/>
                </body>
              </body>
            </body>
          </body>
        </body>
      </body>
      <!-- Link hip_2 -->
      <body name="hip_2" pos="-0.0584461 0.0466603 -0.0421933" quat="0.298836 0.640856 0.640856 0.298836">
        <!-- Joint from body to hip_2 -->
        <joint axis="0 0 1" name="left_hip_roll" type="hinge" range="-1 1" frictionloss="0.052" armature="0.028" damping="0"/>
        <inertial pos="0.0010905 -0.0362656 0.0188233" mass="0.0855956" fullinertia="2.91207e-05 2.11816e-05 3.40671e-05 2.71351e-07 2.44685e-09 -9.18667e-09"/>
        <!-- Part sts3250_8 -->
        <geom type="mesh" class="visual" pos="0.14699 -0.04 -0.045685" quat="0.707107 -1.88963e-15 -0.707107 -4.77396e-15" mesh="sts3250" material="sts3250_material"/>
        <geom type="mesh" class="collision" pos="0.14699 -0.04 -0.045685" quat="0.707107 -1.88963e-15 -0.707107 -4.77396e-15" mesh="sts3250" material="sts3250_material"/>
        <!-- Part hips1016_2 -->
        <geom type="mesh" class="visual" pos="0.016 0 0.018825" quat="0.707107 -0.707107 0 6.34268e-32" mesh="hips1016" material="hips1016_material"/>
        <geom type="mesh" class="collision" pos="0.016 0 0.018825" quat="0.707107 -0.707107 0 6.34268e-32" mesh="hips1016" material="hips1016_material"/>
        <!-- Link low_hip_2 -->
        <body name="low_hip_2" pos="-0.0186 -0.05 0.018825" quat="0.640856 0.298836 0.640856 0.298836">
          <!-- Joint from hip_2 to low_hip_2 -->
          <joint axis="0 0 1" name="left_hip_pitch" type="hinge" range="-1.6 1.6" frictionloss="0.052" armature="0.028" damping="0"/>
          <inertial pos="-0.040824 -1.59298e-06 0.00773057" mass="0.0933278" fullinertia="2.8675e-05 4.55973e-05 3.05392e-05 1.83928e-09 -3.21234e-06 8.78737e-09"/>
          <!-- Part sts3250_9 -->
          <geom type="mesh" class="visual" pos="0.10099 -0.06451 0.008825" quat="0.5 -0.5 -0.5 0.5" mesh="sts3250" material="sts3250_material"/>
          <geom type="mesh" class="collision" pos="0.10099 -0.06451 0.008825" quat="0.5 -0.5 -0.5 0.5" mesh="sts3250" material="sts3250_material"/>
          <!-- Part thigh1111_2 -->
          <geom type="mesh" class="visual" pos="-0.03 0 -0.031175" quat="6.91522e-15 -1 -0 -2.06731e-33" mesh="thigh1111" material="thigh1111_material"/>
          <geom type="mesh" class="collision" pos="-0.03 0 -0.031175" quat="6.91522e-15 -1 -0 -2.06731e-33" mesh="thigh1111" material="thigh1111_material"/>
          <!-- Link knee_down_2 -->
          <body name="knee_down_2" pos="-0.02695 -6.80012e-16 0.018825" quat="0.707107 4.85723e-15 0.707107 4.85029e-15">
            <!-- Joint from low_hip_2 to knee_down_2 -->
            <joint axis="0 0 1" name="left_hip_yaw" type="hinge" range="-0.785 0.785" frictionloss="0.052" armature="0.028" damping="0"/>
            <inertial pos="-0.0107349 2.97228e-18 -0.0263596" mass="0.0153484" fullinertia="1.08234e-05 8.20048e-06 4.71676e-06 -5.53683e-36 7.91036e-07 -7.78716e-37"/>
            <!-- Part knee_down_2 -->
            <geom type="mesh" class="visual" pos="-6.93889e-18 0 -0.038" quat="0.707107 0.707107 0 -2.20657e-31" mesh="knee_down" material="knee_down_material"/>
            <geom type="mesh" class="collision" pos="-6.93889e-18 0 -0.038" quat="0.707107 0.707107 0 -2.20657e-31" mesh="knee_down" material="knee_down_material"/>
            <!-- Link knee_2 -->
            <body name="knee_2" pos="1.38778e-17 -0.019 -0.059" quat="0.707107 0.707107 -0 -1.96262e-17">
              <!-- Joint from knee_down_2 to knee_2 -->
              <joint axis="0 0 1" name="left_knee" type="hinge" range="-1.23 1.6" frictionloss="0.052" armature="0.028" damping="0"/>
              <inertial pos="-1.6645e-06 -0.014753 -0.0180095" mass="0.089322" fullinertia="4.06015e-05 2.34719e-05 3.03909e-05 9.3381e-09 2.45428e-09 -3.70177e-07"/>
              <!-- Part calf1028_2 -->
              <geom type="mesh" class="visual" pos="4.44089e-16 -0.0500539 -0.00305001" quat="0.5 0.5 -0.5 0.5" mesh="calf1028" material="calf1028_material"/>
              <geom type="mesh" class="collision" pos="4.44089e-16 -0.0500539 -0.00305001" quat="0.5 0.5 -0.5 0.5" mesh="calf1028" material="calf1028_material"/>
              <!-- Part sts3250_10 -->
              <geom type="mesh" class="visual" pos="-0.06451 -0.01 0.12794" quat="0 1 0 0" mesh="sts3250" material="sts3250_material"/>
              <geom type="mesh" class="collision" pos="-0.06451 -0.01 0.12794" quat="0 1 0 0" mesh="sts3250" material="sts3250_material"/>
              <!-- Link sts3250_2 -->
              <body name="sts3250_2" pos="4.3715e-16 -0.0500539 -0.000225009" quat="1 -4.2567e-16 -6.66134e-16 -8.32667e-17">
                <!-- Joint from knee_2 to sts3250_2 -->
                <joint axis="0 0 1" name="left_ankle_pitch" type="hinge" frictionloss="0.052" armature="0.028" damping="0"/>
                <inertial pos="0.025329 -0.0124373 -0.0184884" mass="0.165746" fullinertia="5.38947e-05 0.000143797 0.000159121 2.76741e-07 2.3552e-06 -1.51221e-07"/>
                <!-- Part sts3250_11 -->
                <geom type="mesh" class="visual" pos="-0.06451 -0.01 0.12794" quat="0 1 0 0" mesh="sts3250" material="sts3250_material"/>
                <geom type="mesh" class="collision" pos="-0.06451 -0.01 0.12794" quat="0 1 0 0" mesh="sts3250" material="sts3250_material"/>
                <!-- Part sts3250_12 -->
                <geom type="mesh" class="visual" pos="-0.09499 -0.014834 0.04546" quat="0.707107 3.50507e-17 0.707107 -4.44089e-16" mesh="sts3250" material="sts3250_material"/>
                <geom type="mesh" class="collision" pos="-0.09499 -0.014834 0.04546" quat="0.707107 3.50507e-17 0.707107 -4.44089e-16" mesh="sts3250" material="sts3250_material"/>
                <!-- Part left_ankle0120 -->
                <geom type="mesh" class="visual" pos="-6.93889e-18 -0.035054 -0.01905" quat="6.63765e-17 1 2.1684e-18 -3.31051e-17" mesh="left_ankle0120" material="left_ankle0120_material"/>
                <geom type="mesh" class="collision" pos="-6.93889e-18 -0.035054 -0.01905" quat="6.63765e-17 1 2.1684e-18 -3.31051e-17" mesh="left_ankle0120" material="left_ankle0120_material"/>
                <!-- Link left_foot0120 -->
                <body name="left_foot0120" pos="0.03295 -0.024834 -0.01905" quat="0.707107 3.50507e-17 0.707107 -4.44089e-16">
                  <!-- Joint from sts3250_2 to left_foot0120 -->
                  <joint axis="0 0 1" name="left_ankle_roll" type="hinge" frictionloss="0.052" armature="0.028" damping="0"/>
                  <inertial pos="-0.0154683 -0.0283057 -0.0290094" mass="0.069069" fullinertia="0.000175929 0.000210947 4.03005e-05 -1.73185e-06 -3.54868e-06 -2.96376e-06"/>
                  <!-- Part left_foot0120 -->
                  <geom type="mesh" class="visual" pos="-0.016 -0.01 0.018825" quat="7.435e-16 8.32667e-16 0.707107 0.707107" mesh="left_foot0120" material="left_foot0120_material"/>
                  <geom type="mesh" class="collision" pos="-0.016 -0.01 0.018825" quat="7.435e-16 8.32667e-16 0.707107 0.707107" mesh="left_foot0120" material="left_foot0120_material"/>
                </body>
              </body>
            </body>
          </body>
        </body>
      </body>
    </body>
  </worldbody>
  <asset>
    <mesh file="max4466__3.stl"/>
    <mesh file="left_wrist0124.stl"/>
    <mesh file="left_paw0215.stl"/>
    <mesh file="torso_short0212.stl"/>
    <mesh file="leg_foundation.stl"/>
    <mesh file="sts3215.stl"/>
    <mesh file="calf1028.stl"/>
    <mesh file="tricep0219.stl"/>
    <mesh file="right_wrist0124.stl"/>
    <mesh file="thumb_0112.stl"/>
    <mesh file="head1209.stl"/>
    <mesh file="sts3250.stl"/>
    <mesh file="realsense_d435i.stl"/>
    <mesh file="thigh1111.stl"/>
    <mesh file="shoulder0219.stl"/>
    <mesh file="right_foot0120.stl"/>
    <mesh file="left_foot0120.stl"/>
    <mesh file="bicep0215.stl"/>
    <mesh file="max4466.stl"/>
    <mesh file="hips1016.stl"/>
    <mesh file="left_ankle0120.stl"/>
    <mesh file="knee_down.stl"/>
    <mesh file="max4466__2.stl"/>
    <mesh file="leg_adapter.stl"/>
    <mesh file="right_paw0215.stl"/>
    <mesh file="internal_weight_395g__configuration_default.stl"/>
    <mesh file="right_ankle0120.stl"/>
    <material name="leg_foundation_material" rgba="1 1 1 1"/>
    <material name="sts3250_material" rgba="0.4 0.4 0.4 1"/>
    <material name="torso_short0212_material" rgba="1 1 1 1"/>
    <material name="leg_adapter_material" rgba="1 1 1 1"/>
    <material name="sts3215_material" rgba="0.4 0.4 0.4 1"/>
    <material name="internal_weight_395g__configuration_default_material" rgba="0.615686 0.811765 0.929412 1"/>
    <material name="max4466_material" rgba="0.368627 0.25098 0.643137 1"/>
    <material name="realsense_d435i_material" rgba="0.866667 0.909804 1 1"/>
    <material name="max4466__2_material" rgba="0.8 0.8 0.8 1"/>
    <material name="head1209_material" rgba="1 1 1 1"/>
    <material name="max4466__3_material" rgba="0.262745 0.282353 0.301961 1"/>
    <material name="shoulder0219_material" rgba="1 1 1 1"/>
    <material name="tricep0219_material" rgba="1 1 1 1"/>
    <material name="bicep0215_material" rgba="1 1 1 1"/>
    <material name="right_wrist0124_material" rgba="1 1 1 1"/>
    <material name="right_paw0215_material" rgba="1 1 1 1"/>
    <material name="thumb_0112_material" rgba="0.717647 0.717647 0.717647 1"/>
    <material name="hips1016_material" rgba="1 1 1 1"/>
    <material name="thigh1111_material" rgba="0.717647 0.717647 0.717647 1"/>
    <material name="knee_down_material" rgba="1 1 1 1"/>
    <material name="calf1028_material" rgba="1 1 1 1"/>
    <material name="right_ankle0120_material" rgba="0.717647 0.717647 0.717647 1"/>
    <material name="right_foot0120_material" rgba="0.717647 0.717647 0.717647 1"/>
    <material name="left_wrist0124_material" rgba="1 1 1 1"/>
    <material name="left_paw0215_material" rgba="1 1 1 1"/>
    <material name="left_ankle0120_material" rgba="0.717647 0.717647 0.717647 1"/>
    <material name="left_foot0120_material" rgba="0.717647 0.717647 0.717647 1"/>
  </asset>
  <actuator>
    <position class="SundayA1_Mujoco" name="head_yaw" joint="head_yaw" inheritrange="1"/>
    <position class="SundayA1_Mujoco" name="right_shoulder_pitch" joint="right_shoulder_pitch" inheritrange="1"/>
    <position class="SundayA1_Mujoco" name="right_shoulder_roll" joint="right_shoulder_roll" inheritrange="1"/>
    <position class="SundayA1_Mujoco" name="right_shoulder_yaw" joint="right_shoulder_yaw"/>
    <position class="SundayA1_Mujoco" name="right_elbow_pitch" joint="right_elbow_pitch"/>
    <position class="SundayA1_Mujoco" name="right_wrist_yaw" joint="right_wrist_yaw"/>
    <position class="SundayA1_Mujoco" name="right_hand" joint="right_hand" inheritrange="1"/>
    <position class="SundayA1_Mujoco" name="right_hip_roll" joint="right_hip_roll" inheritrange="1"/>
    <position class="SundayA1_Mujoco" name="right_hip_pitch" joint="right_hip_pitch" inheritrange="1"/>
    <position class="SundayA1_Mujoco" name="right_hip_yaw" joint="right_hip_yaw" inheritrange="1"/>
    <position class="SundayA1_Mujoco" name="right_knee" joint="right_knee" inheritrange="1"/>
    <position class="SundayA1_Mujoco" name="right_ankle_pitch" joint="right_ankle_pitch"/>
    <position class="SundayA1_Mujoco" name="right_ankle_roll" joint="right_ankle_roll"/>
    <position class="SundayA1_Mujoco" name="left_shoulder_pitch" joint="left_shoulder_pitch" inheritrange="1"/>
    <position class="SundayA1_Mujoco" name="left_shoulder_roll" joint="left_shoulder_roll" inheritrange="1"/>
    <position class="SundayA1_Mujoco" name="left_shoulder_yaw" joint="left_shoulder_yaw"/>
    <position class="SundayA1_Mujoco" name="left_elbow_pitch" joint="left_elbow_pitch"/>
    <position class="SundayA1_Mujoco" name="left_wrist_yaw" joint="left_wrist_yaw"/>
    <position class="SundayA1_Mujoco" name="left_hand" joint="left_hand" inheritrange="1"/>
    <position class="SundayA1_Mujoco" name="left_hip_roll" joint="left_hip_roll" inheritrange="1"/>
    <position class="SundayA1_Mujoco" name="left_hip_pitch" joint="left_hip_pitch" inheritrange="1"/>
    <position class="SundayA1_Mujoco" name="left_hip_yaw" joint="left_hip_yaw" inheritrange="1"/>
    <position class="SundayA1_Mujoco" name="left_knee" joint="left_knee" inheritrange="1"/>
    <position class="SundayA1_Mujoco" name="left_ankle_pitch" joint="left_ankle_pitch"/>
    <position class="SundayA1_Mujoco" name="left_ankle_roll" joint="left_ankle_roll"/>
  </actuator>
  <equality/>
</mujoco>
