<?xml version="1.0" ?>
<!-- Generated using onshape-to-robot -->
<!-- Onshape https://cad.onshape.com/documents/75898e4f36dccdb8f47bca25/w/e47b7562b7a7768436f44aef/e/ba58a3f077f6fae09dbedcba -->
<robot name="SundayA1_URDF">
  <!-- Link body -->
  <link name="body">
    <inertial>
      <origin xyz="-1.6949e-08 0.0488643 0.0348685" rpy="0 0 0"/>
      <mass value="0.919437"/>
      <inertia ixx="0.00340985" ixy="8.0934e-10" ixz="3.16401e-06" iyy="0.0045585" iyz="-0.000216638" izz="0.0026209"/>
    </inertial>
    <!-- Part leg_foundation -->
    <visual>
      <origin xyz="-0.0245693 0.0466603 -0.0314571" rpy="2.44346 -1.11022e-16 -1.5708"/>
      <geometry>
        <mesh filename="assets/leg_foundation.stl"/>
      </geometry>
      <material name="leg_foundation_material">
        <color rgba="1 1 1 1"/>
      </material>
    </visual>
    <collision>
      <origin xyz="-0.0245693 0.0466603 -0.0314571" rpy="2.44346 -1.11022e-16 -1.5708"/>
      <geometry>
        <mesh filename="assets/leg_foundation.stl"/>
      </geometry>
    </collision>
    <!-- Part sts3250 -->
    <visual>
      <origin xyz="0.150026 0.11117 0.0477053" rpy="2.26893 1.83946e-16 -1.5708"/>
      <geometry>
        <mesh filename="assets/sts3250.stl"/>
      </geometry>
      <material name="sts3250_material">
        <color rgba="0.4 0.4 0.4 1"/>
      </material>
    </visual>
    <collision>
      <origin xyz="0.150026 0.11117 0.0477053" rpy="2.26893 1.83946e-16 -1.5708"/>
      <geometry>
        <mesh filename="assets/sts3250.stl"/>
      </geometry>
    </collision>
    <!-- Part torso_short0212 -->
    <visual>
      <origin xyz="-3.65721e-18 0.0466603 0.035" rpy="-7.7707e-51 1.04492e-16 -3.14159"/>
      <geometry>
        <mesh filename="assets/torso_short0212.stl"/>
      </geometry>
      <material name="torso_short0212_material">
        <color rgba="1 1 1 1"/>
      </material>
    </visual>
    <collision>
      <origin xyz="-3.65721e-18 0.0466603 0.035" rpy="-7.7707e-51 1.04492e-16 -3.14159"/>
      <geometry>
        <mesh filename="assets/torso_short0212.stl"/>
      </geometry>
    </collision>
    <!-- Part leg_adapter -->
    <visual>
      <origin xyz="-0.0323 0.0466603 -0.008" rpy="1.5708 -1.04492e-16 4.5388e-33"/>
      <geometry>
        <mesh filename="assets/leg_adapter.stl"/>
      </geometry>
      <material name="leg_adapter_material">
        <color rgba="1 1 1 1"/>
      </material>
    </visual>
    <collision>
      <origin xyz="-0.0323 0.0466603 -0.008" rpy="1.5708 -1.04492e-16 4.5388e-33"/>
      <geometry>
        <mesh filename="assets/leg_adapter.stl"/>
      </geometry>
    </collision>
    <!-- Part leg_foundation_2 -->
    <visual>
      <origin xyz="0.0245693 0.0466603 -0.0314571" rpy="2.44346 -2.22045e-16 1.5708"/>
      <geometry>
        <mesh filename="assets/leg_foundation.stl"/>
      </geometry>
      <material name="leg_foundation_2_material">
        <color rgba="1 1 1 1"/>
      </material>
    </visual>
    <collision>
      <origin xyz="0.0245693 0.0466603 -0.0314571" rpy="2.44346 -2.22045e-16 1.5708"/>
      <geometry>
        <mesh filename="assets/leg_foundation.stl"/>
      </geometry>
    </collision>
    <!-- Part sts3250_2 -->
    <visual>
      <origin xyz="-0.150026 -0.0178497 0.0477053" rpy="2.26893 -1.27074e-16 1.5708"/>
      <geometry>
        <mesh filename="assets/sts3250.stl"/>
      </geometry>
      <material name="sts3250_2_material">
        <color rgba="0.4 0.4 0.4 1"/>
      </material>
    </visual>
    <collision>
      <origin xyz="-0.150026 -0.0178497 0.0477053" rpy="2.26893 -1.27074e-16 1.5708"/>
      <geometry>
        <mesh filename="assets/sts3250.stl"/>
      </geometry>
    </collision>
    <!-- Part sts3215 -->
    <visual>
      <origin xyz="0.06451 0.0548603 0.26339" rpy="3.14159 3.60697e-16 3.14159"/>
      <geometry>
        <mesh filename="assets/sts3215.stl"/>
      </geometry>
      <material name="sts3215_material">
        <color rgba="0.4 0.4 0.4 1"/>
      </material>
    </visual>
    <collision>
      <origin xyz="0.06451 0.0548603 0.26339" rpy="3.14159 3.60697e-16 3.14159"/>
      <geometry>
        <mesh filename="assets/sts3215.stl"/>
      </geometry>
    </collision>
    <!-- Part leg_adapter_2 -->
    <visual>
      <origin xyz="0.0323 0.0466603 -0.008" rpy="1.5708 1.04492e-16 -3.14159"/>
      <geometry>
        <mesh filename="assets/leg_adapter.stl"/>
      </geometry>
      <material name="leg_adapter_2_material">
        <color rgba="1 1 1 1"/>
      </material>
    </visual>
    <collision>
      <origin xyz="0.0323 0.0466603 -0.008" rpy="1.5708 1.04492e-16 -3.14159"/>
      <geometry>
        <mesh filename="assets/leg_adapter.stl"/>
      </geometry>
    </collision>
    <!-- Part sts3215_2 -->
    <visual>
      <origin xyz="-0.21099 0.11117 0.082" rpy="-1.5708 5.58907e-20 -1.5708"/>
      <geometry>
        <mesh filename="assets/sts3215.stl"/>
      </geometry>
      <material name="sts3215_2_material">
        <color rgba="0.4 0.4 0.4 1"/>
      </material>
    </visual>
    <collision>
      <origin xyz="-0.21099 0.11117 0.082" rpy="-1.5708 5.58907e-20 -1.5708"/>
      <geometry>
        <mesh filename="assets/sts3215.stl"/>
      </geometry>
    </collision>
    <!-- Part internal_weight_395g__configuration_default -->
    <visual>
      <origin xyz="0.0357255 0.0793234 0.05" rpy="-3.14159 -3.50325e-18 3.14159"/>
      <geometry>
        <mesh filename="assets/internal_weight_395g__configuration_default.stl"/>
      </geometry>
      <material name="internal_weight_395g__configuration_default_material">
        <color rgba="0.615686 0.811765 0.929412 1"/>
      </material>
    </visual>
    <collision>
      <origin xyz="0.0357255 0.0793234 0.05" rpy="-3.14159 -3.50325e-18 3.14159"/>
      <geometry>
        <mesh filename="assets/internal_weight_395g__configuration_default.stl"/>
      </geometry>
    </collision>
    <!-- Part sts3215_3 -->
    <visual>
      <origin xyz="0.21099 -0.0178497 0.081254" rpy="-1.5708 -1.2326e-32 1.5708"/>
      <geometry>
        <mesh filename="assets/sts3215.stl"/>
      </geometry>
      <material name="sts3215_3_material">
        <color rgba="0.4 0.4 0.4 1"/>
      </material>
    </visual>
    <collision>
      <origin xyz="0.21099 -0.0178497 0.081254" rpy="-1.5708 -1.2326e-32 1.5708"/>
      <geometry>
        <mesh filename="assets/sts3215.stl"/>
      </geometry>
    </collision>
  </link>
  <!-- Link head1209 -->
  <link name="head1209">
    <inertial>
      <origin xyz="0 0 0" rpy="0 0 0"/>
      <mass value="1e-09"/>
      <inertia ixx="1e-09" ixy="0" ixz="0" iyy="1e-09" iyz="0" izz="1e-09"/>
    </inertial>
    <!-- Part max4466 -->
    <visual>
      <origin xyz="-0.0090644 0.01609 -0.0636732" rpy="1.5708 -1.77636e-16 -6.09207e-20"/>
      <geometry>
        <mesh filename="assets/max4466.stl"/>
      </geometry>
      <material name="max4466_material">
        <color rgba="0.368627 0.25098 0.643137 1"/>
      </material>
    </visual>
    <collision>
      <origin xyz="-0.0090644 0.01609 -0.0636732" rpy="1.5708 -1.77636e-16 -6.09207e-20"/>
      <geometry>
        <mesh filename="assets/max4466.stl"/>
      </geometry>
    </collision>
    <!-- Part realsense_d435i -->
    <visual>
      <origin xyz="-1.85941e-17 0.00146458 -0.0981134" rpy="-1.0472 -5.15738e-16 -3.7389e-16"/>
      <geometry>
        <mesh filename="assets/realsense_d435i.stl"/>
      </geometry>
      <material name="realsense_d435i_material">
        <color rgba="0.866667 0.909804 1 1"/>
      </material>
    </visual>
    <collision>
      <origin xyz="-1.85941e-17 0.00146458 -0.0981134" rpy="-1.0472 -5.15738e-16 -3.7389e-16"/>
      <geometry>
        <mesh filename="assets/realsense_d435i.stl"/>
      </geometry>
    </collision>
    <!-- Part max4466_2 -->
    <visual>
      <origin xyz="0.00885766 0.01609 -0.0313509" rpy="-1.5708 6.14786e-16 -3.14159"/>
      <geometry>
        <mesh filename="assets/max4466__2.stl"/>
      </geometry>
      <material name="max4466_2_material">
        <color rgba="0.8 0.8 0.8 1"/>
      </material>
    </visual>
    <collision>
      <origin xyz="0.00885766 0.01609 -0.0313509" rpy="-1.5708 6.14786e-16 -3.14159"/>
      <geometry>
        <mesh filename="assets/max4466__2.stl"/>
      </geometry>
    </collision>
    <!-- Part head1209 -->
    <visual>
      <origin xyz="-1.5992e-17 0.0225 -0.09" rpy="3.14159 -1.77636e-16 -6.14999e-20"/>
      <geometry>
        <mesh filename="assets/head1209.stl"/>
      </geometry>
      <material name="head1209_material">
        <color rgba="1 1 1 1"/>
      </material>
    </visual>
    <collision>
      <origin xyz="-1.5992e-17 0.0225 -0.09" rpy="3.14159 -1.77636e-16 -6.14999e-20"/>
      <geometry>
        <mesh filename="assets/head1209.stl"/>
      </geometry>
    </collision>
    <!-- Part max4466_3 -->
    <visual>
      <origin xyz="0.00885766 0.01609 -0.0313509" rpy="-1.5708 6.14786e-16 -3.14159"/>
      <geometry>
        <mesh filename="assets/max4466__3.stl"/>
      </geometry>
      <material name="max4466_3_material">
        <color rgba="0.262745 0.282353 0.301961 1"/>
      </material>
    </visual>
    <collision>
      <origin xyz="0.00885766 0.01609 -0.0313509" rpy="-1.5708 6.14786e-16 -3.14159"/>
      <geometry>
        <mesh filename="assets/max4466__3.stl"/>
      </geometry>
    </collision>
  </link>
  <!-- Joint from body to head1209 -->
  <joint name="head_yaw" type="revolute">
    <origin xyz="-2.67391e-17 0.0448603 0.13545" rpy="-3.14159 -3.1481e-28 -3.13699"/>
    <parent link="body"/>
    <child link="head1209"/>
    <axis xyz="0 0 1"/>
    <limit effort="1.9" velocity="5" lower="-1" upper="1"/>
    <joint_properties friction="0.052"/>
  </joint>
  <!-- Link shoulder -->
  <link name="shoulder">
    <inertial>
      <origin xyz="-7.74179e-08 0.0146453 0.00369943" rpy="0 0 0"/>
      <mass value="0.0259955"/>
      <inertia ixx="2.22226e-05" ixy="-3.73679e-12" ixz="-5.71921e-11" iyy="2.49882e-05" iyz="-1.99158e-08" izz="5.15337e-06"/>
    </inertial>
    <!-- Part shoulder0219 -->
    <visual>
      <origin xyz="6.93889e-18 1.38778e-17 1.38778e-17" rpy="-1.5708 -2.27051e-17 -1.5708"/>
      <geometry>
        <mesh filename="assets/shoulder0219.stl"/>
      </geometry>
      <material name="shoulder0219_material">
        <color rgba="1 1 1 1"/>
      </material>
    </visual>
    <collision>
      <origin xyz="6.93889e-18 1.38778e-17 1.38778e-17" rpy="-1.5708 -2.27051e-17 -1.5708"/>
      <geometry>
        <mesh filename="assets/shoulder0219.stl"/>
      </geometry>
    </collision>
  </link>
  <!-- Link sts3215 -->
  <link name="sts3215">
    <inertial>
      <origin xyz="0.0396149 -1.73498e-06 -0.0251363" rpy="0 0 0"/>
      <mass value="0.149789"/>
      <inertia ixx="4.79732e-05" ixy="-5.66256e-09" ixz="2.71954e-05" iyy="0.000171303" iyz="1.01133e-08" izz="0.000148054"/>
    </inertial>
    <!-- Part tricep0219 -->
    <visual>
      <origin xyz="0.026159 2.22045e-16 -0.01905" rpy="-1.5708 1.69398e-16 -1.5708"/>
      <geometry>
        <mesh filename="assets/tricep0219.stl"/>
      </geometry>
      <material name="tricep0219_material">
        <color rgba="1 1 1 1"/>
      </material>
    </visual>
    <collision>
      <origin xyz="0.026159 2.22045e-16 -0.01905" rpy="-1.5708 1.69398e-16 -1.5708"/>
      <geometry>
        <mesh filename="assets/tricep0219.stl"/>
      </geometry>
    </collision>
    <!-- Part sts3215_4 -->
    <visual>
      <origin xyz="0.213149 -0.06451 -0.028996" rpy="-1.5708 -1.69398e-16 1.5708"/>
      <geometry>
        <mesh filename="assets/sts3215.stl"/>
      </geometry>
      <material name="sts3215_4_material">
        <color rgba="0.4 0.4 0.4 1"/>
      </material>
    </visual>
    <collision>
      <origin xyz="0.213149 -0.06451 -0.028996" rpy="-1.5708 -1.69398e-16 1.5708"/>
      <geometry>
        <mesh filename="assets/sts3215.stl"/>
      </geometry>
    </collision>
    <!-- Part sts3215_5 -->
    <visual>
      <origin xyz="0.01 -0.06451 0.12794" rpy="-3.14159 8.22863e-33 1.5708"/>
      <geometry>
        <mesh filename="assets/sts3215.stl"/>
      </geometry>
      <material name="sts3215_5_material">
        <color rgba="0.4 0.4 0.4 1"/>
      </material>
    </visual>
    <collision>
      <origin xyz="0.01 -0.06451 0.12794" rpy="-3.14159 8.22863e-33 1.5708"/>
      <geometry>
        <mesh filename="assets/sts3215.stl"/>
      </geometry>
    </collision>
  </link>
  <!-- Link bicep0215 -->
  <link name="bicep0215">
    <inertial>
      <origin xyz="-3.43692e-08 0.0105064 0.0304454" rpy="0 0 0"/>
      <mass value="0.0164132"/>
      <inertia ixx="9.00476e-06" ixy="-2.27858e-12" ixz="-2.22701e-11" iyy="1.06984e-05" iyz="8.80917e-07" izz="4.20346e-06"/>
    </inertial>
    <!-- Part bicep0215 -->
    <visual>
      <origin xyz="0 0 0.038" rpy="-1.5708 4.16334e-17 -1.5708"/>
      <geometry>
        <mesh filename="assets/bicep0215.stl"/>
      </geometry>
      <material name="bicep0215_material">
        <color rgba="1 1 1 1"/>
      </material>
    </visual>
    <collision>
      <origin xyz="0 0 0.038" rpy="-1.5708 4.16334e-17 -1.5708"/>
      <geometry>
        <mesh filename="assets/bicep0215.stl"/>
      </geometry>
    </collision>
  </link>
  <!-- Link right_wrist0124 -->
  <link name="right_wrist0124">
    <inertial>
      <origin xyz="-0.00672825 -0.039208 -0.0185055" rpy="0 0 0"/>
      <mass value="0.149081"/>
      <inertia ixx="0.000152342" ixy="-2.32758e-05" ixz="-5.5014e-07" iyy="4.52601e-05" iyz="-2.30887e-06" izz="0.000162039"/>
    </inertial>
    <!-- Part sts3215_6 -->
    <visual>
      <origin xyz="-0.06451 -0.01 0.12794" rpy="3.14159 -5.6055e-30 0"/>
      <geometry>
        <mesh filename="assets/sts3215.stl"/>
      </geometry>
      <material name="sts3215_6_material">
        <color rgba="0.4 0.4 0.4 1"/>
      </material>
    </visual>
    <collision>
      <origin xyz="-0.06451 -0.01 0.12794" rpy="3.14159 -5.6055e-30 0"/>
      <geometry>
        <mesh filename="assets/sts3215.stl"/>
      </geometry>
    </collision>
    <!-- Part right_wrist0124 -->
    <visual>
      <origin xyz="1.38778e-17 -0.026159 -0.01905" rpy="1.5708 -1.5708 0"/>
      <geometry>
        <mesh filename="assets/right_wrist0124.stl"/>
      </geometry>
      <material name="right_wrist0124_material">
        <color rgba="1 1 1 1"/>
      </material>
    </visual>
    <collision>
      <origin xyz="1.38778e-17 -0.026159 -0.01905" rpy="1.5708 -1.5708 0"/>
      <geometry>
        <mesh filename="assets/right_wrist0124.stl"/>
      </geometry>
    </collision>
    <!-- Part sts3215_7 -->
    <visual>
      <origin xyz="-0.01 -0.213149 0.04546" rpy="-1.5708 1.5708 0"/>
      <geometry>
        <mesh filename="assets/sts3215.stl"/>
      </geometry>
      <material name="sts3215_7_material">
        <color rgba="0.4 0.4 0.4 1"/>
      </material>
    </visual>
    <collision>
      <origin xyz="-0.01 -0.213149 0.04546" rpy="-1.5708 1.5708 0"/>
      <geometry>
        <mesh filename="assets/sts3215.stl"/>
      </geometry>
    </collision>
  </link>
  <!-- Link right_hand -->
  <link name="right_hand">
    <inertial>
      <origin xyz="-0.000729897 -0.00113781 -0.0212412" rpy="0 0 0"/>
      <mass value="0.107683"/>
      <inertia ixx="7.60984e-05" ixy="-9.19788e-08" ixz="-5.77082e-07" iyy="7.06376e-05" iyz="1.24624e-05" izz="3.80343e-05"/>
    </inertial>
    <!-- Part sts3215_8 -->
    <visual>
      <origin xyz="-0.14699 -0.002554 0.03651" rpy="5.93657e-14 1.5708 0"/>
      <geometry>
        <mesh filename="assets/sts3215.stl"/>
      </geometry>
      <material name="sts3215_8_material">
        <color rgba="0.4 0.4 0.4 1"/>
      </material>
    </visual>
    <collision>
      <origin xyz="-0.14699 -0.002554 0.03651" rpy="5.93657e-14 1.5708 0"/>
      <geometry>
        <mesh filename="assets/sts3215.stl"/>
      </geometry>
    </collision>
    <!-- Part right_paw0215 -->
    <visual>
      <origin xyz="-0.016 9.64506e-16 -0.025" rpy="-3.14159 -1.33003e-27 3.14159"/>
      <geometry>
        <mesh filename="assets/right_paw0215.stl"/>
      </geometry>
      <material name="right_paw0215_material">
        <color rgba="1 1 1 1"/>
      </material>
    </visual>
    <collision>
      <origin xyz="-0.016 9.64506e-16 -0.025" rpy="-3.14159 -1.33003e-27 3.14159"/>
      <geometry>
        <mesh filename="assets/right_paw0215.stl"/>
      </geometry>
    </collision>
  </link>
  <!-- Link thumb_0112 -->
  <link name="thumb_0112">
    <inertial>
      <origin xyz="0.0270123 -0.00215478 -0.018825" rpy="0 0 0"/>
      <mass value="0.0051587"/>
      <inertia ixx="8.61073e-07" ixy="2.48224e-07" ixz="4.40556e-15" iyy="2.19119e-06" iyz="1.59335e-14" izz="1.56579e-06"/>
    </inertial>
    <!-- Part thumb_0112 -->
    <visual>
      <origin xyz="-1.38778e-17 0 -0.018825" rpy="-1.5708 2.39757e-16 -1.51295"/>
      <geometry>
        <mesh filename="assets/thumb_0112.stl"/>
      </geometry>
      <material name="thumb_0112_material">
        <color rgba="0.717647 0.717647 0.717647 1"/>
      </material>
    </visual>
    <collision>
      <origin xyz="-1.38778e-17 0 -0.018825" rpy="-1.5708 2.39757e-16 -1.51295"/>
      <geometry>
        <mesh filename="assets/thumb_0112.stl"/>
      </geometry>
    </collision>
  </link>
  <!-- Joint from right_hand to thumb_0112 -->
  <joint name="right_hand" type="revolute">
    <origin xyz="-0.01905 -0.012554 -0.028" rpy="-3.14159 1.5708 0"/>
    <parent link="right_hand"/>
    <child link="thumb_0112"/>
    <axis xyz="0 0 1"/>
    <limit effort="1.9" velocity="5" lower="-2.5" upper="0"/>
    <joint_properties friction="0.052"/>
  </joint>
  <!-- Joint from right_wrist0124 to right_hand -->
  <joint name="right_wrist_yaw" type="revolute">
    <origin xyz="5.55112e-17 -0.085209 -0.01905" rpy="-1.5708 1.5708 0"/>
    <parent link="right_wrist0124"/>
    <child link="right_hand"/>
    <axis xyz="0 0 1"/>
    <limit effort="1.9" velocity="5" lower="-3.141592653589793" upper="3.141592653589793"/>
    <joint_properties friction="0.052"/>
  </joint>
  <!-- Joint from bicep0215 to right_wrist0124 -->
  <joint name="right_elbow_pitch" type="revolute">
    <origin xyz="-0.019 -1.01308e-15 0.059" rpy="-1.5708 6.93889e-17 1.5708"/>
    <parent link="bicep0215"/>
    <child link="right_wrist0124"/>
    <axis xyz="0 0 1"/>
    <limit effort="1.9" velocity="5" lower="-3.141592653589793" upper="3.141592653589793"/>
    <joint_properties friction="0.052"/>
  </joint>
  <!-- Joint from sts3215 to bicep0215 -->
  <joint name="right_shoulder_yaw" type="revolute">
    <origin xyz="0.047559 -2.77556e-17 -0.018996" rpy="1.5708 -1.69398e-16 1.5708"/>
    <parent link="sts3215"/>
    <child link="bicep0215"/>
    <axis xyz="0 0 1"/>
    <limit effort="1.9" velocity="5" lower="-3.141592653589793" upper="3.141592653589793"/>
    <joint_properties friction="0.052"/>
  </joint>
  <!-- Joint from shoulder to sts3215 -->
  <joint name="right_shoulder_roll" type="revolute">
    <origin xyz="0.019 0.01 0.049" rpy="-1.5708 4.68455e-15 -1.5708"/>
    <parent link="shoulder"/>
    <child link="sts3215"/>
    <axis xyz="0 0 1"/>
    <limit effort="1.9" velocity="5" lower="-1.7" upper="1.7"/>
    <joint_properties friction="0.052"/>
  </joint>
  <!-- Joint from body to shoulder -->
  <joint name="right_shoulder_pitch" type="revolute">
    <origin xyz="0.08305 0.0466603 0.091254" rpy="1.5708 -1.2326e-32 1.5708"/>
    <parent link="body"/>
    <child link="shoulder"/>
    <axis xyz="0 0 1"/>
    <limit effort="1.9" velocity="5" lower="-0.785" upper="0.785"/>
    <joint_properties friction="0.052"/>
  </joint>
  <!-- Link hip -->
  <link name="hip">
    <inertial>
      <origin xyz="0.0010905 -0.0362656 0.0188233" rpy="0 0 0"/>
      <mass value="0.0855956"/>
      <inertia ixx="2.91207e-05" ixy="2.71351e-07" ixz="2.44685e-09" iyy="2.11816e-05" iyz="-9.18667e-09" izz="3.40671e-05"/>
    </inertial>
    <!-- Part sts3250_3 -->
    <visual>
      <origin xyz="0.14699 -0.04 -0.045685" rpy="9.6299e-16 -1.5708 0"/>
      <geometry>
        <mesh filename="assets/sts3250.stl"/>
      </geometry>
      <material name="sts3250_3_material">
        <color rgba="0.4 0.4 0.4 1"/>
      </material>
    </visual>
    <collision>
      <origin xyz="0.14699 -0.04 -0.045685" rpy="9.6299e-16 -1.5708 0"/>
      <geometry>
        <mesh filename="assets/sts3250.stl"/>
      </geometry>
    </collision>
    <!-- Part hips1016 -->
    <visual>
      <origin xyz="0.016 0 0.018825" rpy="-1.5708 3.09808e-31 -2.14208e-30"/>
      <geometry>
        <mesh filename="assets/hips1016.stl"/>
      </geometry>
      <material name="hips1016_material">
        <color rgba="1 1 1 1"/>
      </material>
    </visual>
    <collision>
      <origin xyz="0.016 0 0.018825" rpy="-1.5708 3.09808e-31 -2.14208e-30"/>
      <geometry>
        <mesh filename="assets/hips1016.stl"/>
      </geometry>
    </collision>
  </link>
  <!-- Link low_hip -->
  <link name="low_hip">
    <inertial>
      <origin xyz="-0.040824 -1.59298e-06 0.00773057" rpy="0 0 0"/>
      <mass value="0.0933278"/>
      <inertia ixx="2.8675e-05" ixy="1.83928e-09" ixz="-3.21234e-06" iyy="4.55973e-05" iyz="8.78737e-09" izz="3.05392e-05"/>
    </inertial>
    <!-- Part sts3250_4 -->
    <visual>
      <origin xyz="0.10099 -0.06451 0.008825" rpy="-1.5708 -3.46055e-14 1.5708"/>
      <geometry>
        <mesh filename="assets/sts3250.stl"/>
      </geometry>
      <material name="sts3250_4_material">
        <color rgba="0.4 0.4 0.4 1"/>
      </material>
    </visual>
    <collision>
      <origin xyz="0.10099 -0.06451 0.008825" rpy="-1.5708 -3.46055e-14 1.5708"/>
      <geometry>
        <mesh filename="assets/sts3250.stl"/>
      </geometry>
    </collision>
    <!-- Part thigh1111 -->
    <visual>
      <origin xyz="-0.03 0 -0.031175" rpy="-3.14159 2.5191e-33 -7.88861e-31"/>
      <geometry>
        <mesh filename="assets/thigh1111.stl"/>
      </geometry>
      <material name="thigh1111_material">
        <color rgba="0.717647 0.717647 0.717647 1"/>
      </material>
    </visual>
    <collision>
      <origin xyz="-0.03 0 -0.031175" rpy="-3.14159 2.5191e-33 -7.88861e-31"/>
      <geometry>
        <mesh filename="assets/thigh1111.stl"/>
      </geometry>
    </collision>
  </link>
  <!-- Link knee_down -->
  <link name="knee_down">
    <inertial>
      <origin xyz="-0.0107349 2.97228e-18 -0.0263596" rpy="0 0 0"/>
      <mass value="0.0153484"/>
      <inertia ixx="1.08234e-05" ixy="-2.9532e-35" ixz="7.91036e-07" iyy="8.20048e-06" iyz="-2.30105e-36" izz="4.71676e-06"/>
    </inertial>
    <!-- Part knee_down -->
    <visual>
      <origin xyz="0 0 -0.038" rpy="1.5708 -0 -2.90891e-30"/>
      <geometry>
        <mesh filename="assets/knee_down.stl"/>
      </geometry>
      <material name="knee_down_material">
        <color rgba="1 1 1 1"/>
      </material>
    </visual>
    <collision>
      <origin xyz="0 0 -0.038" rpy="1.5708 -0 -2.90891e-30"/>
      <geometry>
        <mesh filename="assets/knee_down.stl"/>
      </geometry>
    </collision>
  </link>
  <!-- Link knee -->
  <link name="knee">
    <inertial>
      <origin xyz="-1.6645e-06 0.014753 0.0180095" rpy="0 0 0"/>
      <mass value="0.089322"/>
      <inertia ixx="4.06015e-05" ixy="-9.3381e-09" ixz="-2.45428e-09" iyy="2.34719e-05" iyz="-3.70177e-07" izz="3.03909e-05"/>
    </inertial>
    <!-- Part calf1028 -->
    <visual>
      <origin xyz="3.88578e-16 0.0500539 0.00305001" rpy="-1.5708 1.5708 0"/>
      <geometry>
        <mesh filename="assets/calf1028.stl"/>
      </geometry>
      <material name="calf1028_material">
        <color rgba="1 1 1 1"/>
      </material>
    </visual>
    <collision>
      <origin xyz="3.88578e-16 0.0500539 0.00305001" rpy="-1.5708 1.5708 0"/>
      <geometry>
        <mesh filename="assets/calf1028.stl"/>
      </geometry>
    </collision>
    <!-- Part sts3250_5 -->
    <visual>
      <origin xyz="-0.06451 0.01 -0.12794" rpy="-3.56247e-31 -1.79051e-30 1.35585e-31"/>
      <geometry>
        <mesh filename="assets/sts3250.stl"/>
      </geometry>
      <material name="sts3250_5_material">
        <color rgba="0.4 0.4 0.4 1"/>
      </material>
    </visual>
    <collision>
      <origin xyz="-0.06451 0.01 -0.12794" rpy="-3.56247e-31 -1.79051e-30 1.35585e-31"/>
      <geometry>
        <mesh filename="assets/sts3250.stl"/>
      </geometry>
    </collision>
  </link>
  <!-- Link sts3250 -->
  <link name="sts3250">
    <inertial>
      <origin xyz="-0.0253308 -0.0124615 -0.0184902" rpy="0 0 0"/>
      <mass value="0.165746"/>
      <inertia ixx="5.39066e-05" ixy="-3.60844e-07" ixz="-2.35286e-06" iyy="0.000143783" iyz="-1.71457e-07" izz="0.000159117"/>
    </inertial>
    <!-- Part sts3250_6 -->
    <visual>
      <origin xyz="0.09499 -0.014888 -0.08356" rpy="-1.09947e-29 -1.5708 0"/>
      <geometry>
        <mesh filename="assets/sts3250.stl"/>
      </geometry>
      <material name="sts3250_6_material">
        <color rgba="0.4 0.4 0.4 1"/>
      </material>
    </visual>
    <collision>
      <origin xyz="0.09499 -0.014888 -0.08356" rpy="-1.09947e-29 -1.5708 0"/>
      <geometry>
        <mesh filename="assets/sts3250.stl"/>
      </geometry>
    </collision>
    <!-- Part sts3250_7 -->
    <visual>
      <origin xyz="-0.06451 -0.01 0.12794" rpy="-3.14159 -3.7264e-30 4.93038e-32"/>
      <geometry>
        <mesh filename="assets/sts3250.stl"/>
      </geometry>
      <material name="sts3250_7_material">
        <color rgba="0.4 0.4 0.4 1"/>
      </material>
    </visual>
    <collision>
      <origin xyz="-0.06451 -0.01 0.12794" rpy="-3.14159 -3.7264e-30 4.93038e-32"/>
      <geometry>
        <mesh filename="assets/sts3250.stl"/>
      </geometry>
    </collision>
    <!-- Part right_ankle0120 -->
    <visual>
      <origin xyz="1.38778e-17 -0.035054 -0.01905" rpy="6.64145e-15 7.19553e-15 3.14159"/>
      <geometry>
        <mesh filename="assets/right_ankle0120.stl"/>
      </geometry>
      <material name="right_ankle0120_material">
        <color rgba="0.717647 0.717647 0.717647 1"/>
      </material>
    </visual>
    <collision>
      <origin xyz="1.38778e-17 -0.035054 -0.01905" rpy="6.64145e-15 7.19553e-15 3.14159"/>
      <geometry>
        <mesh filename="assets/right_ankle0120.stl"/>
      </geometry>
    </collision>
  </link>
  <!-- Link right_foot0120 -->
  <link name="right_foot0120">
    <inertial>
      <origin xyz="-0.015468 0.0283055 -0.0290089" rpy="0 0 0"/>
      <mass value="0.0697141"/>
      <inertia ixx="0.000177573" ixy="1.74827e-06" ixz="-3.58318e-06" iyy="0.00021292" iyz="2.99215e-06" izz="4.0677e-05"/>
    </inertial>
    <!-- Part right_foot0120 -->
    <visual>
      <origin xyz="-0.016 0.01 0.018825" rpy="1.5708 1.86507e-30 0"/>
      <geometry>
        <mesh filename="assets/right_foot0120.stl"/>
      </geometry>
      <material name="right_foot0120_material">
        <color rgba="0.717647 0.717647 0.717647 1"/>
      </material>
    </visual>
    <collision>
      <origin xyz="-0.016 0.01 0.018825" rpy="1.5708 1.86507e-30 0"/>
      <geometry>
        <mesh filename="assets/right_foot0120.stl"/>
      </geometry>
    </collision>
  </link>
  <!-- Joint from sts3250 to right_foot0120 -->
  <joint name="right_ankle_roll" type="revolute">
    <origin xyz="-0.03295 -0.024888 -0.01905" rpy="-3.14159 1.5708 0"/>
    <parent link="sts3250"/>
    <child link="right_foot0120"/>
    <axis xyz="0 0 1"/>
    <limit effort="1.9" velocity="5" lower="-3.141592653589793" upper="3.141592653589793"/>
    <joint_properties friction="0.052"/>
  </joint>
  <!-- Joint from knee to sts3250 -->
  <joint name="right_ankle_pitch" type="revolute">
    <origin xyz="3.88578e-16 0.0500539 0.000225009" rpy="-3.14159 -6.87411e-15 -1.63758e-15"/>
    <parent link="knee"/>
    <child link="sts3250"/>
    <axis xyz="0 0 1"/>
    <limit effort="1.9" velocity="5" lower="-3.141592653589793" upper="3.141592653589793"/>
    <joint_properties friction="0.052"/>
  </joint>
  <!-- Joint from knee_down to knee -->
  <joint name="right_knee" type="revolute">
    <origin xyz="1.38778e-17 0.019 -0.059" rpy="-1.5708 -3.95461e-16 -3.14159"/>
    <parent link="knee_down"/>
    <child link="knee"/>
    <axis xyz="0 0 1"/>
    <limit effort="1.9" velocity="5" lower="-1.23" upper="1.6"/>
    <joint_properties friction="0.052"/>
  </joint>
  <!-- Joint from low_hip to knee_down -->
  <joint name="right_hip_yaw" type="revolute">
    <origin xyz="-0.02695 -3.747e-16 0.018825" rpy="8.21838e-17 1.5708 0"/>
    <parent link="low_hip"/>
    <child link="knee_down"/>
    <axis xyz="0 0 1"/>
    <limit effort="1.9" velocity="5" lower="-0.785" upper="0.785"/>
    <joint_properties friction="0.052"/>
  </joint>
  <!-- Joint from hip to low_hip -->
  <joint name="right_hip_pitch" type="revolute">
    <origin xyz="0.01905 -0.05 0.018825" rpy="-1.5708 0.698132 1.5708"/>
    <parent link="hip"/>
    <child link="low_hip"/>
    <axis xyz="0 0 1"/>
    <limit effort="1.9" velocity="5" lower="-1.6" upper="1.6"/>
    <joint_properties friction="0.052"/>
  </joint>
  <!-- Joint from body to hip -->
  <joint name="right_hip_roll" type="revolute">
    <origin xyz="0.0584461 0.0466603 -0.0421933" rpy="2.26893 8.02814e-15 -1.5708"/>
    <parent link="body"/>
    <child link="hip"/>
    <axis xyz="0 0 1"/>
    <limit effort="1.9" velocity="5" lower="-1" upper="1"/>
    <joint_properties friction="0.052"/>
  </joint>
  <!-- Link shoulder_2 -->
  <link name="shoulder_2">
    <inertial>
      <origin xyz="-7.74179e-08 -0.0146453 -0.00369943" rpy="0 0 0"/>
      <mass value="0.0259955"/>
      <inertia ixx="2.22226e-05" ixy="3.73679e-12" ixz="5.71921e-11" iyy="2.49882e-05" iyz="-1.99158e-08" izz="5.15337e-06"/>
    </inertial>
    <!-- Part shoulder0219_2 -->
    <visual>
      <origin xyz="0 0 0" rpy="1.5708 2.59356e-15 1.5708"/>
      <geometry>
        <mesh filename="assets/shoulder0219.stl"/>
      </geometry>
      <material name="shoulder0219_2_material">
        <color rgba="1 1 1 1"/>
      </material>
    </visual>
    <collision>
      <origin xyz="0 0 0" rpy="1.5708 2.59356e-15 1.5708"/>
      <geometry>
        <mesh filename="assets/shoulder0219.stl"/>
      </geometry>
    </collision>
  </link>
  <!-- Link sts3215_2 -->
  <link name="sts3215_2">
    <inertial>
      <origin xyz="-1.73498e-06 -0.0396149 -0.0251363" rpy="0 0 0"/>
      <mass value="0.149789"/>
      <inertia ixx="0.000171303" ixy="5.66256e-09" ixz="1.01133e-08" iyy="4.79732e-05" iyz="-2.71954e-05" izz="0.000148054"/>
    </inertial>
    <!-- Part sts3215_9 -->
    <visual>
      <origin xyz="-0.06451 -0.213149 -0.028996" rpy="-1.5708 -5.0482e-17 5.7945e-31"/>
      <geometry>
        <mesh filename="assets/sts3215.stl"/>
      </geometry>
      <material name="sts3215_9_material">
        <color rgba="0.4 0.4 0.4 1"/>
      </material>
    </visual>
    <collision>
      <origin xyz="-0.06451 -0.213149 -0.028996" rpy="-1.5708 -5.0482e-17 5.7945e-31"/>
      <geometry>
        <mesh filename="assets/sts3215.stl"/>
      </geometry>
    </collision>
    <!-- Part tricep0219_2 -->
    <visual>
      <origin xyz="1.94289e-16 -0.026159 -0.01905" rpy="-1.5708 5.0482e-17 3.14159"/>
      <geometry>
        <mesh filename="assets/tricep0219.stl"/>
      </geometry>
      <material name="tricep0219_2_material">
        <color rgba="1 1 1 1"/>
      </material>
    </visual>
    <collision>
      <origin xyz="1.94289e-16 -0.026159 -0.01905" rpy="-1.5708 5.0482e-17 3.14159"/>
      <geometry>
        <mesh filename="assets/tricep0219.stl"/>
      </geometry>
    </collision>
    <!-- Part sts3215_10 -->
    <visual>
      <origin xyz="-0.06451 -0.01 0.12794" rpy="3.14159 1.50288e-32 -2.09411e-31"/>
      <geometry>
        <mesh filename="assets/sts3215.stl"/>
      </geometry>
      <material name="sts3215_10_material">
        <color rgba="0.4 0.4 0.4 1"/>
      </material>
    </visual>
    <collision>
      <origin xyz="-0.06451 -0.01 0.12794" rpy="3.14159 1.50288e-32 -2.09411e-31"/>
      <geometry>
        <mesh filename="assets/sts3215.stl"/>
      </geometry>
    </collision>
  </link>
  <!-- Link bicep0215_2 -->
  <link name="bicep0215_2">
    <inertial>
      <origin xyz="0.000838992 -0.0104729 0.00755461" rpy="0 0 0"/>
      <mass value="0.0164132"/>
      <inertia ixx="9.01556e-06" ixy="-1.34816e-07" ixz="-7.03264e-08" iyy="1.06876e-05" iyz="8.78105e-07" izz="4.20346e-06"/>
    </inertial>
    <!-- Part bicep0215_2 -->
    <visual>
      <origin xyz="0 0 0" rpy="1.5708 -9.56513e-17 1.65074"/>
      <geometry>
        <mesh filename="assets/bicep0215.stl"/>
      </geometry>
      <material name="bicep0215_2_material">
        <color rgba="1 1 1 1"/>
      </material>
    </visual>
    <collision>
      <origin xyz="0 0 0" rpy="1.5708 -9.56513e-17 1.65074"/>
      <geometry>
        <mesh filename="assets/bicep0215.stl"/>
      </geometry>
    </collision>
  </link>
  <!-- Link sts3215_3 -->
  <link name="sts3215_3">
    <inertial>
      <origin xyz="0.00670296 -0.039208 -0.0185072" rpy="0 0 0"/>
      <mass value="0.149081"/>
      <inertia ixx="0.000152342" ixy="2.31994e-05" ixz="5.38439e-07" iyy="4.52341e-05" iyz="-2.32039e-06" izz="0.000162013"/>
    </inertial>
    <!-- Part sts3215_11 -->
    <visual>
      <origin xyz="0.009946 -0.213149 -0.08356" rpy="-1.5708 -1.5708 0"/>
      <geometry>
        <mesh filename="assets/sts3215.stl"/>
      </geometry>
      <material name="sts3215_11_material">
        <color rgba="0.4 0.4 0.4 1"/>
      </material>
    </visual>
    <collision>
      <origin xyz="0.009946 -0.213149 -0.08356" rpy="-1.5708 -1.5708 0"/>
      <geometry>
        <mesh filename="assets/sts3215.stl"/>
      </geometry>
    </collision>
    <!-- Part left_wrist0124 -->
    <visual>
      <origin xyz="-4.92661e-16 -0.026159 -0.01905" rpy="1.5708 -1.5708 0"/>
      <geometry>
        <mesh filename="assets/left_wrist0124.stl"/>
      </geometry>
      <material name="left_wrist0124_material">
        <color rgba="1 1 1 1"/>
      </material>
    </visual>
    <collision>
      <origin xyz="-4.92661e-16 -0.026159 -0.01905" rpy="1.5708 -1.5708 0"/>
      <geometry>
        <mesh filename="assets/left_wrist0124.stl"/>
      </geometry>
    </collision>
    <!-- Part sts3215_12 -->
    <visual>
      <origin xyz="-0.06451 -0.01 0.12794" rpy="3.14159 1.97549e-18 2.77784e-31"/>
      <geometry>
        <mesh filename="assets/sts3215.stl"/>
      </geometry>
      <material name="sts3215_12_material">
        <color rgba="0.4 0.4 0.4 1"/>
      </material>
    </visual>
    <collision>
      <origin xyz="-0.06451 -0.01 0.12794" rpy="3.14159 1.97549e-18 2.77784e-31"/>
      <geometry>
        <mesh filename="assets/sts3215.stl"/>
      </geometry>
    </collision>
  </link>
  <!-- Link left_hand -->
  <link name="left_hand">
    <inertial>
      <origin xyz="0.000639307 -0.00115995 -0.0212436" rpy="0 0 0"/>
      <mass value="0.107683"/>
      <inertia ixx="7.60784e-05" ixy="-3.45493e-07" ixz="1.57548e-06" iyy="7.06616e-05" iyz="1.23844e-05" izz="3.80313e-05"/>
    </inertial>
    <!-- Part sts3215_13 -->
    <visual>
      <origin xyz="0.146321 -0.0142304 -0.09251" rpy="-0.0799435 -1.5708 0"/>
      <geometry>
        <mesh filename="assets/sts3215.stl"/>
      </geometry>
      <material name="sts3215_13_material">
        <color rgba="0.4 0.4 0.4 1"/>
      </material>
    </visual>
    <collision>
      <origin xyz="0.146321 -0.0142304 -0.09251" rpy="-0.0799435 -1.5708 0"/>
      <geometry>
        <mesh filename="assets/sts3215.stl"/>
      </geometry>
    </collision>
    <!-- Part left_paw0215 -->
    <visual>
      <origin xyz="0.0159489 -0.00127773 -0.025" rpy="-3.14159 2.51174e-16 -0.0799435"/>
      <geometry>
        <mesh filename="assets/left_paw0215.stl"/>
      </geometry>
      <material name="left_paw0215_material">
        <color rgba="1 1 1 1"/>
      </material>
    </visual>
    <collision>
      <origin xyz="0.0159489 -0.00127773 -0.025" rpy="-3.14159 2.51174e-16 -0.0799435"/>
      <geometry>
        <mesh filename="assets/left_paw0215.stl"/>
      </geometry>
    </collision>
  </link>
  <!-- Link thumb_0112_2 -->
  <link name="thumb_0112_2">
    <inertial>
      <origin xyz="-0.0268425 0.00371289 0.018825" rpy="0 0 0"/>
      <mass value="0.0051587"/>
      <inertia ixx="8.94173e-07" ixy="3.23337e-07" ixz="-5.31938e-15" iyy="2.15809e-06" iyz="-1.56522e-14" izz="1.56579e-06"/>
    </inertial>
    <!-- Part thumb_0112_2 -->
    <visual>
      <origin xyz="0 2.08167e-17 0.018825" rpy="-1.5708 2.0324e-14 1.5708"/>
      <geometry>
        <mesh filename="assets/thumb_0112.stl"/>
      </geometry>
      <material name="thumb_0112_2_material">
        <color rgba="0.717647 0.717647 0.717647 1"/>
      </material>
    </visual>
    <collision>
      <origin xyz="0 2.08167e-17 0.018825" rpy="-1.5708 2.0324e-14 1.5708"/>
      <geometry>
        <mesh filename="assets/thumb_0112.stl"/>
      </geometry>
    </collision>
  </link>
  <!-- Joint from left_hand to thumb_0112_2 -->
  <joint name="left_hand" type="revolute">
    <origin xyz="0.0179909 -0.0139814 -0.028" rpy="-0.0799435 -1.5708 0"/>
    <parent link="left_hand"/>
    <child link="thumb_0112_2"/>
    <axis xyz="0 0 1"/>
    <limit effort="1.9" velocity="5" lower="0" upper="2.5"/>
    <joint_properties friction="0.052"/>
  </joint>
  <!-- Joint from sts3215_3 to left_hand -->
  <joint name="left_wrist_yaw" type="revolute">
    <origin xyz="-5.4e-05 -0.085209 -0.01905" rpy="-1.5708 -1.5708 0"/>
    <parent link="sts3215_3"/>
    <child link="left_hand"/>
    <axis xyz="0 0 1"/>
    <limit effort="1.9" velocity="5" lower="-3.141592653589793" upper="3.141592653589793"/>
    <joint_properties friction="0.052"/>
  </joint>
  <!-- Joint from bicep0215_2 to sts3215_3 -->
  <joint name="left_elbow_pitch" type="revolute">
    <origin xyz="0.0189393 0.00151731 -0.021" rpy="1.5708 4.60192e-16 1.65074"/>
    <parent link="bicep0215_2"/>
    <child link="sts3215_3"/>
    <axis xyz="0 0 1"/>
    <limit effort="1.9" velocity="5" lower="-3.141592653589793" upper="3.141592653589793"/>
    <joint_properties friction="0.052"/>
  </joint>
  <!-- Joint from sts3215_2 to bicep0215_2 -->
  <joint name="left_shoulder_yaw" type="revolute">
    <origin xyz="-4.16334e-16 -0.085209 -0.018996" rpy="-1.5708 -5.0482e-17 5.7945e-31"/>
    <parent link="sts3215_2"/>
    <child link="bicep0215_2"/>
    <axis xyz="0 0 1"/>
    <limit effort="1.9" velocity="5" lower="-3.141592653589793" upper="3.141592653589793"/>
    <joint_properties friction="0.052"/>
  </joint>
  <!-- Joint from shoulder_2 to sts3215_2 -->
  <joint name="left_shoulder_roll" type="revolute">
    <origin xyz="-0.019 -0.01 -0.049" rpy="3.14159 1.5708 0"/>
    <parent link="shoulder_2"/>
    <child link="sts3215_2"/>
    <axis xyz="0 0 1"/>
    <limit effort="1.9" velocity="5" lower="-1.7" upper="1.7"/>
    <joint_properties friction="0.052"/>
  </joint>
  <!-- Joint from body to shoulder_2 -->
  <joint name="left_shoulder_pitch" type="revolute">
    <origin xyz="-0.08305 0.0466603 0.092" rpy="-1.5708 5.58907e-20 -1.5708"/>
    <parent link="body"/>
    <child link="shoulder_2"/>
    <axis xyz="0 0 1"/>
    <limit effort="1.9" velocity="5" lower="-0.785" upper="0.785"/>
    <joint_properties friction="0.052"/>
  </joint>
  <!-- Link hip_2 -->
  <link name="hip_2">
    <inertial>
      <origin xyz="0.0010905 -0.0362656 0.0188233" rpy="0 0 0"/>
      <mass value="0.0855956"/>
      <inertia ixx="2.91207e-05" ixy="2.71351e-07" ixz="2.44685e-09" iyy="2.11816e-05" iyz="-9.18667e-09" izz="3.40671e-05"/>
    </inertial>
    <!-- Part sts3250_8 -->
    <visual>
      <origin xyz="0.14699 -0.04 -0.045685" rpy="-3.63835e-17 -1.5708 0"/>
      <geometry>
        <mesh filename="assets/sts3250.stl"/>
      </geometry>
      <material name="sts3250_8_material">
        <color rgba="0.4 0.4 0.4 1"/>
      </material>
    </visual>
    <collision>
      <origin xyz="0.14699 -0.04 -0.045685" rpy="-3.63835e-17 -1.5708 0"/>
      <geometry>
        <mesh filename="assets/sts3250.stl"/>
      </geometry>
    </collision>
    <!-- Part hips1016_2 -->
    <visual>
      <origin xyz="0.016 0 0.018825" rpy="-1.5708 5.30656e-31 -1.32744e-31"/>
      <geometry>
        <mesh filename="assets/hips1016.stl"/>
      </geometry>
      <material name="hips1016_2_material">
        <color rgba="1 1 1 1"/>
      </material>
    </visual>
    <collision>
      <origin xyz="0.016 0 0.018825" rpy="-1.5708 5.30656e-31 -1.32744e-31"/>
      <geometry>
        <mesh filename="assets/hips1016.stl"/>
      </geometry>
    </collision>
  </link>
  <!-- Link low_hip_2 -->
  <link name="low_hip_2">
    <inertial>
      <origin xyz="-0.040824 -1.59298e-06 0.00773057" rpy="0 0 0"/>
      <mass value="0.0933278"/>
      <inertia ixx="2.8675e-05" ixy="1.83928e-09" ixz="-3.21234e-06" iyy="4.55973e-05" iyz="8.78737e-09" izz="3.05392e-05"/>
    </inertial>
    <!-- Part sts3250_9 -->
    <visual>
      <origin xyz="0.10099 -0.06451 0.008825" rpy="-1.5708 -1.39882e-14 1.5708"/>
      <geometry>
        <mesh filename="assets/sts3250.stl"/>
      </geometry>
      <material name="sts3250_9_material">
        <color rgba="0.4 0.4 0.4 1"/>
      </material>
    </visual>
    <collision>
      <origin xyz="0.10099 -0.06451 0.008825" rpy="-1.5708 -1.39882e-14 1.5708"/>
      <geometry>
        <mesh filename="assets/sts3250.stl"/>
      </geometry>
    </collision>
    <!-- Part thigh1111_2 -->
    <visual>
      <origin xyz="-0.03 0 -0.031175" rpy="-3.14159 2.62115e-31 -2.46519e-31"/>
      <geometry>
        <mesh filename="assets/thigh1111.stl"/>
      </geometry>
      <material name="thigh1111_2_material">
        <color rgba="0.717647 0.717647 0.717647 1"/>
      </material>
    </visual>
    <collision>
      <origin xyz="-0.03 0 -0.031175" rpy="-3.14159 2.62115e-31 -2.46519e-31"/>
      <geometry>
        <mesh filename="assets/thigh1111.stl"/>
      </geometry>
    </collision>
  </link>
  <!-- Link knee_down_2 -->
  <link name="knee_down_2">
    <inertial>
      <origin xyz="-0.0107349 2.97228e-18 -0.0263596" rpy="0 0 0"/>
      <mass value="0.0153484"/>
      <inertia ixx="1.08234e-05" ixy="-5.53683e-36" ixz="7.91036e-07" iyy="8.20048e-06" iyz="-7.78716e-37" izz="4.71676e-06"/>
    </inertial>
    <!-- Part knee_down_2 -->
    <visual>
      <origin xyz="-6.93889e-18 0 -0.038" rpy="1.5708 -0 -9.84425e-31"/>
      <geometry>
        <mesh filename="assets/knee_down.stl"/>
      </geometry>
      <material name="knee_down_2_material">
        <color rgba="1 1 1 1"/>
      </material>
    </visual>
    <collision>
      <origin xyz="-6.93889e-18 0 -0.038" rpy="1.5708 -0 -9.84425e-31"/>
      <geometry>
        <mesh filename="assets/knee_down.stl"/>
      </geometry>
    </collision>
  </link>
  <!-- Link knee_2 -->
  <link name="knee_2">
    <inertial>
      <origin xyz="-1.6645e-06 -0.014753 -0.0180095" rpy="0 0 0"/>
      <mass value="0.089322"/>
      <inertia ixx="4.06015e-05" ixy="9.3381e-09" ixz="2.45428e-09" iyy="2.34719e-05" iyz="-3.70177e-07" izz="3.03909e-05"/>
    </inertial>
    <!-- Part calf1028_2 -->
    <visual>
      <origin xyz="4.44089e-16 -0.0500539 -0.00305001" rpy="1.5708 -1.5708 0"/>
      <geometry>
        <mesh filename="assets/calf1028.stl"/>
      </geometry>
      <material name="calf1028_2_material">
        <color rgba="1 1 1 1"/>
      </material>
    </visual>
    <collision>
      <origin xyz="4.44089e-16 -0.0500539 -0.00305001" rpy="1.5708 -1.5708 0"/>
      <geometry>
        <mesh filename="assets/calf1028.stl"/>
      </geometry>
    </collision>
    <!-- Part sts3250_10 -->
    <visual>
      <origin xyz="-0.06451 -0.01 0.12794" rpy="3.14159 -5.80026e-31 0"/>
      <geometry>
        <mesh filename="assets/sts3250.stl"/>
      </geometry>
      <material name="sts3250_10_material">
        <color rgba="0.4 0.4 0.4 1"/>
      </material>
    </visual>
    <collision>
      <origin xyz="-0.06451 -0.01 0.12794" rpy="3.14159 -5.80026e-31 0"/>
      <geometry>
        <mesh filename="assets/sts3250.stl"/>
      </geometry>
    </collision>
  </link>
  <!-- Link sts3250_2 -->
  <link name="sts3250_2">
    <inertial>
      <origin xyz="0.025329 -0.0124373 -0.0184884" rpy="0 0 0"/>
      <mass value="0.165746"/>
      <inertia ixx="5.38947e-05" ixy="2.76741e-07" ixz="2.3552e-06" iyy="0.000143797" iyz="-1.51221e-07" izz="0.000159121"/>
    </inertial>
    <!-- Part sts3250_11 -->
    <visual>
      <origin xyz="-0.06451 -0.01 0.12794" rpy="3.14159 -1.93078e-31 2.14163e-31"/>
      <geometry>
        <mesh filename="assets/sts3250.stl"/>
      </geometry>
      <material name="sts3250_11_material">
        <color rgba="0.4 0.4 0.4 1"/>
      </material>
    </visual>
    <collision>
      <origin xyz="-0.06451 -0.01 0.12794" rpy="3.14159 -1.93078e-31 2.14163e-31"/>
      <geometry>
        <mesh filename="assets/sts3250.stl"/>
      </geometry>
    </collision>
    <!-- Part sts3250_12 -->
    <visual>
      <origin xyz="-0.09499 -0.014834 0.04546" rpy="1.95677e-15 1.5708 0"/>
      <geometry>
        <mesh filename="assets/sts3250.stl"/>
      </geometry>
      <material name="sts3250_12_material">
        <color rgba="0.4 0.4 0.4 1"/>
      </material>
    </visual>
    <collision>
      <origin xyz="-0.09499 -0.014834 0.04546" rpy="1.95677e-15 1.5708 0"/>
      <geometry>
        <mesh filename="assets/sts3250.stl"/>
      </geometry>
    </collision>
    <!-- Part left_ankle0120 -->
    <visual>
      <origin xyz="-6.93889e-18 -0.035054 -0.01905" rpy="3.14159 -1.3242e-16 -6.93889e-18"/>
      <geometry>
        <mesh filename="assets/left_ankle0120.stl"/>
      </geometry>
      <material name="left_ankle0120_material">
        <color rgba="0.717647 0.717647 0.717647 1"/>
      </material>
    </visual>
    <collision>
      <origin xyz="-6.93889e-18 -0.035054 -0.01905" rpy="3.14159 -1.3242e-16 -6.93889e-18"/>
      <geometry>
        <mesh filename="assets/left_ankle0120.stl"/>
      </geometry>
    </collision>
  </link>
  <!-- Link left_foot0120 -->
  <link name="left_foot0120">
    <inertial>
      <origin xyz="-0.0154683 -0.0283057 -0.0290094" rpy="0 0 0"/>
      <mass value="0.069069"/>
      <inertia ixx="0.000175929" ixy="-1.73185e-06" ixz="-3.54868e-06" iyy="0.000210947" iyz="-2.96376e-06" izz="4.03005e-05"/>
    </inertial>
    <!-- Part left_foot0120 -->
    <visual>
      <origin xyz="-0.016 -0.01 0.018825" rpy="1.5708 -8.86997e-29 3.14159"/>
      <geometry>
        <mesh filename="assets/left_foot0120.stl"/>
      </geometry>
      <material name="left_foot0120_material">
        <color rgba="0.717647 0.717647 0.717647 1"/>
      </material>
    </visual>
    <collision>
      <origin xyz="-0.016 -0.01 0.018825" rpy="1.5708 -8.86997e-29 3.14159"/>
      <geometry>
        <mesh filename="assets/left_foot0120.stl"/>
      </geometry>
    </collision>
  </link>
  <!-- Joint from sts3250_2 to left_foot0120 -->
  <joint name="left_ankle_roll" type="revolute">
    <origin xyz="0.03295 -0.024834 -0.01905" rpy="1.95677e-15 1.5708 0"/>
    <parent link="sts3250_2"/>
    <child link="left_foot0120"/>
    <axis xyz="0 0 1"/>
    <limit effort="1.9" velocity="5" lower="-3.141592653589793" upper="3.141592653589793"/>
    <joint_properties friction="0.052"/>
  </joint>
  <!-- Joint from knee_2 to sts3250_2 -->
  <joint name="left_ankle_pitch" type="revolute">
    <origin xyz="4.3715e-16 -0.0500539 -0.000225009" rpy="-1.14425e-15 -4.01503e-15 9.82924e-16"/>
    <parent link="knee_2"/>
    <child link="sts3250_2"/>
    <axis xyz="0 0 1"/>
    <limit effort="1.9" velocity="5" lower="-3.141592653589793" upper="3.141592653589793"/>
    <joint_properties friction="0.052"/>
  </joint>
  <!-- Joint from knee_down_2 to knee_2 -->
  <joint name="left_knee" type="revolute">
    <origin xyz="1.38778e-17 -0.019 -0.059" rpy="1.5708 6.12323e-17 5.72119e-18"/>
    <parent link="knee_down_2"/>
    <child link="knee_2"/>
    <axis xyz="0 0 1"/>
    <limit effort="1.9" velocity="5" lower="-1.23" upper="1.6"/>
    <joint_properties friction="0.052"/>
  </joint>
  <!-- Joint from low_hip_2 to knee_down_2 -->
  <joint name="left_hip_yaw" type="revolute">
    <origin xyz="-0.02695 -6.80012e-16 0.018825" rpy="-1.39523e-18 1.5708 0"/>
    <parent link="low_hip_2"/>
    <child link="knee_down_2"/>
    <axis xyz="0 0 1"/>
    <limit effort="1.9" velocity="5" lower="-0.785" upper="0.785"/>
    <joint_properties friction="0.052"/>
  </joint>
  <!-- Joint from hip_2 to low_hip_2 -->
  <joint name="left_hip_pitch" type="revolute">
    <origin xyz="-0.0186 -0.05 0.018825" rpy="1.5708 0.698132 1.5708"/>
    <parent link="hip_2"/>
    <child link="low_hip_2"/>
    <axis xyz="0 0 1"/>
    <limit effort="1.9" velocity="5" lower="-1.6" upper="1.6"/>
    <joint_properties friction="0.052"/>
  </joint>
  <!-- Joint from body to hip_2 -->
  <joint name="left_hip_roll" type="revolute">
    <origin xyz="-0.0584461 0.0466603 -0.0421933" rpy="2.26893 4.62985e-15 1.5708"/>
    <parent link="body"/>
    <child link="hip_2"/>
    <axis xyz="0 0 1"/>
    <limit effort="1.9" velocity="5" lower="-1" upper="1"/>
    <joint_properties friction="0.052"/>
  </joint>
</robot>
